Workbook

Sheet README
A1: PNA business forecast - unit economics, 12-month outlook, 3-year scenarios, business-model economics, sensitivity
A2: Economics & Market Sizing agent, 2026-10-16. Build script: economics/build_scripts/build_business_forecast.py (run via run_all.py).
A4: Status | B4: Illustrative, assumption-driven planning model. PNA's actual revenue, fees, costs and enrolments are NOT known; the baseline is CA-01 (<60 students, base 50) x assumed fees (CA-02).
A5: Scenarios | B5: Conservative = adverse rates + ₹10L plan; Base = base rates + ₹30L plan; Aggressive = favourable rates + ₹50L plan. Rates vs plan are typed in Assumptions column J; Plan10L_BaseRates and Plan50L_BaseRates isolate the envelope choice (BM stress test 7).
A6: Alignment | B6: Growth agent: ladder L1-L5, A-GRO-01..50, paid-media ramp and team lines (growth_marketing_strategy.md §10). BM agent: realised L3 fee A-BM-02 (₹65k/80k/1.0L), batch cap 12, trainer pay A-BM-04, founder path A-BM-10, pop-ups A-BM-06, gates G0-G3b.
A7: Price | B7: L3 list ₹90k (A-GRO-06) vs realised ₹80k (A-BM-02): revenue uses realised. Until the proof gate (A-ECO-104: M7 base, M5 aggressive, not in Y1 conservative) PNA charges today's fee CA-02 (₹40k/60k/75k) incl. kit.
A8: Enrolment engine | B8: Career demand = seasonality x speed-to-lead factor x [non-paid share x plan target + MIN(paid share x target, budget x career share / effective paid CAC)], then limited by seat capacity. Effective CAC = funnel paid-route CAC x overhead factor calibrated so the Base budget buys the Base target.
A9: GST | B9: 18% GST on private non-recognised training (A-ECO-23, GST Council flyer). Base assumes quoted fees include GST (revenue = fee/1.18); Flex_gst_ontop shows charging it on top.
A10: Cash | B10: Net cash flow = EBITDA + instalment timing (A-ECO-34) - capex/deposits. Excludes income tax, GST input/output timing and any founder draw. Peak cash need is compared with the plan envelope (CA-03).
A11: Sheets | B11: Dashboard ; Assumptions ; Unit_Economics ; Capacity ; 3yr_Scenarios ; Sensitivity ; BM_Unit_Economics ; Outlook_* (x3 scenarios + Selected + 2 cross runs) ; Flex_* (sensitivity re-runs) ; Checks

Sheet Dashboard
A1: PNA business forecast - dashboard (₹ lakh unless stated; ex-GST; illustrative, assumption-driven)
A2: Scenario = rates + plan bundle. Conservative = adverse rates + ₹10L plan; Base = base rates + ₹30L plan; Aggressive = favourable rates + ₹50L plan. Cross runs show the ₹10L / ₹50L plans at Base rates.
A4: Year-1 (Nov-26 to Oct-27) | B4: Conservative | C4: Base | D4: Aggressive | E4: ₹10L plan @ Base rates | F4: ₹50L plan @ Base rates | G4: Note
A5: Revenue, Year 1 (ex-GST) | B5: =Outlook_Conservative!B109/100000 -> 16.714396 | C5: =Outlook_Base!B109/100000 -> 71.143533 | D5: =Outlook_Aggressive!B109/100000 -> 134.55428 | E5: =Plan10L_BaseRates!B109/100000 -> 38.134814 | F5: =Plan50L_BaseRates!B109/100000 -> 99.929187
A6: EBITDA, Year 1 | B6: =Outlook_Conservative!B110/100000 -> -13.554457 | C6: =Outlook_Base!B110/100000 -> 5.5146551 | D6: =Outlook_Aggressive!B110/100000 -> 35.066478 | E6: =Plan10L_BaseRates!B110/100000 -> 9.5491944 | F6: =Plan50L_BaseRates!B110/100000 -> -4.5479306
A7: EBITDA margin, Year 1 | B7: =Outlook_Conservative!B111 -> -0.81094506 | C7: =Outlook_Base!B111 -> 0.077514496 | D7: =Outlook_Aggressive!B111 -> 0.26061213 | E7: =Plan10L_BaseRates!B111 -> 0.25040622 | F7: =Plan50L_BaseRates!B111 -> -0.045511534
A8: Memo: Year-1 EBITDA after founder-role salary | B8: =Outlook_Conservative!B112/100000 -> -22.554457 | C8: =Outlook_Base!B112/100000 -> -3.4853449 | D8: =Outlook_Aggressive!B112/100000 -> 26.066478 | E8: =Plan10L_BaseRates!B112/100000 -> 0.54919441 | F8: =Plan50L_BaseRates!B112/100000 -> -13.547931
A9: Capex and deposits, Year 1 | B9: =Outlook_Conservative!B113/100000 -> 0.5 | C9: =Outlook_Base!B113/100000 -> 19.72 | D9: =Outlook_Aggressive!B113/100000 -> 27.04 | E9: =Plan10L_BaseRates!B113/100000 -> 0.5 | F9: =Plan50L_BaseRates!B113/100000 -> 27.04
A10: Peak cumulative cash need, Year 1 | B10: =Outlook_Conservative!B114/100000 -> 15.443217 | C10: =Outlook_Base!B114/100000 -> 26.142235 | D10: =Outlook_Aggressive!B114/100000 -> 28.80706 | E10: =Plan10L_BaseRates!B114/100000 -> 4.1372074 | F10: =Plan50L_BaseRates!B114/100000 -> 45.361828
A11: Investment envelope for this plan (CA-03) | B11: =Outlook_Conservative!B115/100000 -> 10 | C11: =Outlook_Base!B115/100000 -> 30 | D11: =Outlook_Aggressive!B115/100000 -> 50 | E11: =Plan10L_BaseRates!B115/100000 -> 10 | F11: =Plan50L_BaseRates!B115/100000 -> 50
A12: Headroom: envelope - peak cash need | B12: =Outlook_Conservative!B116/100000 -> -5.4432169 | C12: =Outlook_Base!B116/100000 -> 3.8577648 | D12: =Outlook_Aggressive!B116/100000 -> 21.19294 | E12: =Plan10L_BaseRates!B116/100000 -> 5.8627926 | F12: =Plan50L_BaseRates!B116/100000 -> 4.638172
A13: Career enrolments, Year 1 (new students) | B13: =Outlook_Conservative!B117 -> 30.376401 | C13: =Outlook_Base!B117 -> 89.450184 | D13: =Outlook_Aggressive!B117 -> 123.22992 | E13: =Plan10L_BaseRates!B117 -> 48.427721 | F13: =Plan50L_BaseRates!B117 -> 126.54821
A14: Career enrolments per month, months 7-12 average | B14: =Outlook_Conservative!B118 -> 3.6359065 | C14: =Outlook_Base!B118 -> 10.852623 | D14: =Outlook_Aggressive!B118 -> 13.744387 | E14: =Plan10L_BaseRates!B118 -> 5.4336396 | F14: =Plan50L_BaseRates!B118 -> 14.788083
A15: Masterclass seats, Year 1 | B15: =Outlook_Conservative!B119 -> 67.5 | C15: =Outlook_Base!B119 -> 153 | D15: =Outlook_Aggressive!B119 -> 202.5 | E15: =Plan10L_BaseRates!B119 -> 76.5 | F15: =Plan50L_BaseRates!B119 -> 191.25
A16: Seat utilisation, month 12 | B16: =Outlook_Conservative!B120 -> 0.4834982 | C16: =Outlook_Base!B120 -> 0.84101366 | D16: =Outlook_Aggressive!B120 -> 0.9 | E16: =Plan10L_BaseRates!B120 -> 0.80232434 | F16: =Plan50L_BaseRates!B120 -> 0.9
A17: First month seats bind (share of demand that fits < 100%) | B17: =Outlook_Conservative!B121 -> not in Y1 | C17: =Outlook_Base!B121 -> 6 | D17: =Outlook_Aggressive!B121 -> 7 | E17: =Plan10L_BaseRates!B121 -> 8 | F17: =Plan50L_BaseRates!B121 -> 7
A18: Founder share of contact hours, month 12 | B18: =Outlook_Conservative!B122 -> 0.4 | C18: =Outlook_Base!B122 -> 0.3 | D18: =Outlook_Aggressive!B122 -> 0.25 | E18: =Plan10L_BaseRates!B122 -> 0.4 | F18: =Plan50L_BaseRates!B122 -> 0.25
A19: Trainers + assistants on payroll, month 12 | B19: =Outlook_Conservative!B123 -> 1.5 | C19: =Outlook_Base!B123 -> 3 | D19: =Outlook_Aggressive!B123 -> 4 | E19: =Plan10L_BaseRates!B123 -> 1.5 | F19: =Plan50L_BaseRates!B123 -> 4
A20: Contribution per career enrolment, month 12 (career contribution share) | B20: =Outlook_Conservative!B124 -> 34929.965 | C20: =Outlook_Base!B124 -> 50195.582 | D20: =Outlook_Aggressive!B124 -> 68504.555 | E20: =Plan10L_BaseRates!B124 -> 50420.582 | F20: =Plan50L_BaseRates!B124 -> 50033.241
A21: Break-even career enrolments per month at month-12 cost base | B21: =Outlook_Conservative!B127 -> 4.3555767 | C21: =Outlook_Base!B127 -> 5.4796574 | D21: =Outlook_Aggressive!B127 -> 4.8575808 | E21: =Plan10L_BaseRates!B127 -> 1.0401147 | F21: =Plan50L_BaseRates!B127 -> 10.741123
A22: Break-even career enrolments per year (x12) | B22: =Outlook_Conservative!B128 -> 52.26692 | C22: =Outlook_Base!B128 -> 65.755889 | D22: =Outlook_Aggressive!B128 -> 58.29097 | E22: =Plan10L_BaseRates!B128 -> 12.481377 | F22: =Plan50L_BaseRates!B128 -> 128.89347
A23: Effective media CAC per paid career enrolment, months 7-12 | B23: =Outlook_Conservative!B129 -> 12834.947 | C23: =Outlook_Base!B129 -> 10750.089 | D23: =Outlook_Aggressive!B129 -> 16976.627 | E23: =Plan10L_BaseRates!B129 -> 8588.4729 | F23: =Plan50L_BaseRates!B129 -> 15778.471
A24: Effective media CAC as % of realised L3 fee (ex-GST) | B24: =Outlook_Conservative!B130 -> 0.23300365 | C24: =Outlook_Base!B130 -> 0.15856381 | D24: =Outlook_Aggressive!B130 -> 0.2003242 | E24: =Plan10L_BaseRates!B130 -> 0.12667998 | F24: =Plan50L_BaseRates!B130 -> 0.23273245
A25: Fully loaded acquisition cost / career revenue, months 7-12 (media + growth team + tools + rewards + EMI) | B25: =Outlook_Conservative!B131 -> 0.65089263 | C25: =Outlook_Base!B131 -> 0.42243028 | D25: =Outlook_Aggressive!B131 -> 0.4446932 | E25: =Plan10L_BaseRates!B131 -> 0.27821829 | F25: =Plan50L_BaseRates!B131 -> 0.55094716
A26: Career enrolments per month at which fully loaded acquisition = 25% of career revenue (month-12 cost and price) | B26: =Outlook_Conservative!B132 -> 7.5288401 | C26: =Outlook_Base!B132 -> 17.542883 | D26: =Outlook_Aggressive!B132 -> 23.95295 | E26: =Plan10L_BaseRates!B132 -> 5.6684374 | F26: =Plan50L_BaseRates!B132 -> 31.306627
A27: EBITDA, last quarter (Aug-Oct 2027) | B27: =Outlook_Conservative!B133/100000 -> -1.3244177 | C27: =Outlook_Base!B133/100000 -> 6.6793824 | D27: =Outlook_Aggressive!B133/100000 -> 18.38758 | E27: =Plan10L_BaseRates!B133/100000 -> 5.7054945 | F27: =Plan50L_BaseRates!B133/100000 -> 5.5847348
A28: First month with EBITDA >= 0 | B28: =Outlook_Conservative!B134 -> not in Y1 | C28: =Outlook_Base!B134 -> 7 | D28: =Outlook_Aggressive!B134 -> 5 | E28: =Plan10L_BaseRates!B134 -> 5 | F28: =Plan50L_BaseRates!B134 -> 7
A29: Cash position, end of Year 1 | B29: =Outlook_Conservative!B135/100000 -> -15.443217 | C29: =Outlook_Base!B135/100000 -> -17.129608 | D29: =Outlook_Aggressive!B135/100000 -> 8.0264777 | E29: =Plan10L_BaseRates!B135/100000 -> 7.6455483 | F29: =Plan50L_BaseRates!B135/100000 -> -35.528116
A31: Directional 3-year view (₹ lakh)
A32: Metric | B32: Cons Y1 | C32: Cons Y2 | D32: Cons Y3 | E32: Base Y1 | F32: Base Y2 | G32: Base Y3 | H32: Aggr Y1 | I32: Aggr Y2 | J32: Aggr Y3
A33: Total revenue | B33: =3yr_Scenarios!B38 -> 16.714396 | C33: =3yr_Scenarios!C38 -> 26.631759 | D33: =3yr_Scenarios!D38 -> 36.657299 | E33: =3yr_Scenarios!E38 -> 71.143533 | F33: =3yr_Scenarios!F38 -> 120.01493 | G33: =3yr_Scenarios!G38 -> 166.93116 | H33: =3yr_Scenarios!H38 -> 134.55428 | I33: =3yr_Scenarios!I38 -> 235.65821 | J33: =3yr_Scenarios!J38 -> 334.642
A34: EBITDA | B34: =3yr_Scenarios!B49 -> -13.554457 | C34: =3yr_Scenarios!C49 -> -7.2101524 | D34: =3yr_Scenarios!D49 -> -9.6406418 | E34: =3yr_Scenarios!E49 -> 5.5146551 | F34: =3yr_Scenarios!F49 -> 17.552053 | G34: =3yr_Scenarios!G49 -> 44.836901 | H34: =3yr_Scenarios!H49 -> 35.066478 | I34: =3yr_Scenarios!I49 -> 96.366426 | J34: =3yr_Scenarios!J49 -> 162.74302
A35: EBITDA margin | B35: =3yr_Scenarios!B50 -> -0.81094506 | C35: =3yr_Scenarios!C50 -> -0.27073512 | D35: =3yr_Scenarios!D50 -> -0.26299379 | E35: =3yr_Scenarios!E50 -> 0.077514496 | F35: =3yr_Scenarios!F50 -> 0.14624892 | G35: =3yr_Scenarios!G50 -> 0.26859515 | H35: =3yr_Scenarios!H50 -> 0.26061213 | I35: =3yr_Scenarios!I50 -> 0.40892454 | J35: =3yr_Scenarios!J50 -> 0.48631977
A36: Career enrolments delivered | B36: =3yr_Scenarios!B17 -> 30.376401 | C36: =3yr_Scenarios!C17 -> 38.989295 | D36: =3yr_Scenarios!D17 -> 40.93876 | E36: =3yr_Scenarios!E17 -> 89.450184 | F36: =3yr_Scenarios!F17 -> 121.91883 | G36: =3yr_Scenarios!G17 -> 134.11072 | H36: =3yr_Scenarios!H17 -> 123.22992 | I36: =3yr_Scenarios!I17 -> 160.7633 | J36: =3yr_Scenarios!J17 -> 162.46608
A37: Peak cash need to date | B37: =3yr_Scenarios!B54 -> 15.443217 | C37: =3yr_Scenarios!C54 -> 25.653369 | D37: =3yr_Scenarios!D54 -> 37.994011 | E37: =3yr_Scenarios!E54 -> 26.142235 | F37: =3yr_Scenarios!F54 -> 26.142235 | G37: =3yr_Scenarios!G54 -> 26.142235 | H37: =3yr_Scenarios!H54 -> 28.80706 | I37: =3yr_Scenarios!I54 -> 28.80706 | J37: =3yr_Scenarios!J54 -> 28.80706
A39: Sensitivity (Base Year-1 EBITDA swing, ₹ lakh) - see Sensitivity sheet
A40: =Sensitivity!A6 -> Conversion (all routes; low = founder step-back ÷1.25) | B40: =Sensitivity!F6/100000 -> 13.939746 | C40: =Sensitivity!G6 -> 2 | D40: =Sensitivity!L6 -> ██████████████████
A41: =Sensitivity!A7 -> Fees (all products) | B41: =Sensitivity!F7/100000 -> 23.095618 | C41: =Sensitivity!G7 -> 1 | D41: =Sensitivity!L7 -> ██████████████████████████████
A42: =Sensitivity!A8 -> Cohort fill (students per batch 8 vs 12) | B42: =Sensitivity!F8/100000 -> 2.08 | C42: =Sensitivity!G8 -> 7 | D42: =Sensitivity!L8 -> ███
A43: =Sensitivity!A9 -> CPL / CAC (paid routes) | B43: =Sensitivity!F9/100000 -> 3.0316349 | C43: =Sensitivity!G9 -> 6 | D43: =Sensitivity!L9 -> ████
...

Sheet Assumptions
A1: Assumptions register (inputs)
A2: Blue = input. Scenario columns: Conservative = adverse rates + ₹10L plan; Base = base rates + ₹30L plan; Aggressive = favourable rates + ₹50L plan. Column J 'Type': rate (prices, conversion, wages) or plan (what the plan buys).
A3: Scenario selector | C3: Base | D3: <- choose Conservative / Base / Aggressive (drives column I 'Selected' and any sheet that uses it)
A4: Scenario index | C4: =MATCH($C$3,$K$4:$M$4,0) -> 2 | K4: Conservative | L4: Base | M4: Aggressive
A6: ID | B6: Description | C6: Conservative | D6: Base | E6: Aggressive | F6: Unit | G6: Source / rationale | H6: Tag | I6: Selected | J6: Type
A8: 1. Shared with funnel_economics.xlsx (assumption_values.py): canonical, prices, funnel, delivery costs, Growth budget lines
A9: CA-01 | B9: PNA paying students per year today (all courses) | C9: 30 | D9: 50 | E9: 60 | F9: students/yr | G9: Founder: 'under 60' (2026-10-16) | H9: [FOUNDER] | I9: =INDEX(C9:E9,$C$4) -> 50 | J9: rate
A10: CA-02 | B10: Current flagship professional course fee (incl. kit) | C10: 40000 | D10: 60000 | E10: 75000 | F10: ₹ | G10: Not supplied; local diploma band ₹35-75k (S-LC §6) | H10: [HYP] | I10: =INDEX(C10:E10,$C$4) -> 60000 | J10: rate
A11: CA-03 | B11: Growth investment envelope, 12 months | C11: 1000000 | D11: 3000000 | E11: 5000000 | F11: ₹ | G11: Founder: moderate ₹10-50L | H11: [FOUNDER] | I11: =INDEX(C11:E11,$C$4) -> 3000000 | J11: plan
A12: A-ECO-101 | B12: Career (L2/L3-type) share of today's students | C12: 0.6 | D12: 0.6 | E12: 0.6 | F12: % | G12: Assumed mix; founder data pull (V1) to replace | H12: [HYP] | I12: =INDEX(C12:E12,$C$4) -> 0.6 | J12: rate
A13: A-ECO-102 | B13: Average fee of today's short courses / masterclasses | C13: 6000 | D13: 8000 | E13: 10000 | F13: ₹ | G13: Local short-course band ₹6.5-25k (S-LC §6) | H13: [HYP] | I13: =INDEX(C13:E13,$C$4) -> 8000 | J13: rate
A14: A-ECO-103 | B14: Pro kit cost borne by PNA while fee includes kit (pre price-step) | C14: 15000 | D14: 12000 | E14: 10000 | F14: ₹/student | G14: Growth agent: optional kit ₹18-25k at near cost; basic included kit assumed cheaper | H14: [HYP] | I14: =INDEX(C14:E14,$C$4) -> 12000 | J14: rate
A15: A-ECO-23 | B15: GST rate on PNA training (private, non-recognised; SAC 9992) | C15: 0.18 | D15: 0.18 | E15: 0.18 | F15: % | G15: GST Council education flyer: private/unrecognised coaching not exempt (https://www.gstcouncil.gov.in/sites/default/files/e-version-gst-flyers/GST_Education_Services.pdf, accessed 2026-10-16); AAR Kerala 2022 -> 18% under 9992 | H15: [FACT] rule / [HYP] PNA | I15: =INDEX(C15:E15,$C$4) -> 0.18 | J15: rate
A16: A-ECO-24 | B16: Fees quoted GST-inclusive? (1 = PNA absorbs GST from list fee; 0 = GST charged on top) | C16: 1 | D16: 1 | E16: 1 | F16: switch | G16: Consumer academies mostly quote one number; DBA quotes ex-GST, Pearl incl. GST (S-NC-26, S-IND-23). Sensitivity flips it | H16: [HYP] | I16: =INDEX(C16:E16,$C$4) -> 1 | J16: rate
A17: A-GRO-04 | B17: L1 Career Taster ticket | C17: 999 | D17: 999 | E17: 999 | F17: ₹ | G17: A-GRO-04 base (range ₹499-1,999); credited on enrolment | H17: [HYP] | I17: =INDEX(C17:E17,$C$4) -> 999 | J17: rate
A18: A-GRO-05 | B18: L2 Foundation fee (4 weeks, ~80 h) | C18: 30000 | D18: 39900 | E18: 45000 | F18: ₹ | G18: A-GRO-05 (Aggressive = midpoint of Growth base/high to avoid stacking upsides) | H18: [HYP] | I18: =INDEX(C18:E18,$C$4) -> 39900 | J18: rate
A19: A-GRO-06 | B19: L3 Professional Bridal Programme list tuition (after proof gate; kit optional) | C19: 75000 | D19: 90000 | E19: 120000 | F19: ₹ | G19: A-GRO-06 | H19: [HYP] | I19: =INDEX(C19:E19,$C$4) -> 90000 | J19: rate
A20: A-BM-02 | B20: L3 realised fee after discounts/credits (after proof gate) | C20: 65000 | D20: 80000 | E20: 100000 | F20: ₹ | G20: A-BM-02 (list ₹90k-1.25L) | H20: [HYP] | I20: =INDEX(C20:E20,$C$4) -> 80000 | J20: rate
... A113: A-GRO-50 | B113: SEO content freelancer | C113: 0 | D113: 15000 | E113: 25000 | F113: ₹/mo | G113: Growth §10 | H113: [EST] | I113: =INDEX(C113:E113,$C$4) -> 15000 | J113: plan
A114: 2. Forecast-specific (A-ECO, A-BM, Growth budget ramp, seasonality, 3-year drivers)
A115: A-ECO-FUN-01 | B115: Paid-route media CAC (CTWA + Search + Taster net), from funnel_economics.xlsx Summary | C115: 16680 | D115: 4826 | E115: 1422 | F115: ₹/enrol | G115: Pasted by run_all.py from funnel_economics.xlsx (Funnel_* row 'Paid-route media CAC') | H115: [EST] model output | I115: =INDEX(C115:E115,$C$4) -> 4826 | J115: rate
A116: A-ECO-FUN-02 | B116: Funnel-required career media per month at target, from funnel_economics.xlsx | C116: 64548 | D116: 37633 | E116: 9387 | F116: ₹/mo | G116: Pasted by run_all.py (comparison only) | H116: [EST] model output | I116: =INDEX(C116:E116,$C$4) -> 37633 | J116: rate
A117: A-ECO-FUN-03 | B117: Masterclass media per seat (inside the Growth paid budget), from funnel_economics.xlsx | C117: 1400 | D117: 300 | E117: 43 | F117: ₹/seat | G117: Pasted by run_all.py | H117: [EST] model output | I117: =INDEX(C117:E117,$C$4) -> 300 | J117: rate
A118: A-ECO-FUN-04 | B118: Self-makeup media per seat (inside the Growth paid budget), from funnel_economics.xlsx | C118: 3200 | D118: 706 | E118: 160 | F118: ₹/seat | G118: Pasted by run_all.py | H118: [EST] model output | I118: =INDEX(C118:E118,$C$4) -> 706 | J118: rate
A119: A-ECO-50 | B119: Share of the paid-media budget that buys career (L2/L3) leads | C119: 0.7 | D119: 0.7 | E119: 0.7 | F119: % | G119: marketing_channel_plan.md rows 8-15: career CTWA, regional, Search, brand, taster half of M3, retargeting ≈70% of base ₹1.0L | H119: [EST] | I119: =INDEX(C119:E119,$C$4) -> 0.7 | J119: rate
A120: A-ECO-51 | B120: Awareness/retargeting overhead factor on funnel CAC (calibrated so the Base plan budget buys the Base target at steady state) | C120: =Assumptions!$D$119*Assumptions!$D$132/(Assumptions!$D$25*(Assumptions!$D$27+Assumptions!$D$28+Assumptions!$D$31)*Assumptions!$D$115) -> 2.417461 | D120: =Assumptions!$D$119*Assumptions!$D$132/(Assumptions!$D$25*(Assumptions!$D$27+Assumptions!$D$28+Assumptions!$D$31)*Assumptions!$D$115) -> 2.417461 | E120: =Assumptions!$D$119*Assumptions!$D$132/(Assumptions!$D$25*(Assumptions!$D$27+Assumptions!$D$28+Assumptions!$D$31)*Assumptions!$D$115) -> 2.417461 | F120: x | G120: Calibrated: A-ECO-50 x Base Oct-27 budget / (A-GRO-01 base x paid mix x A-ECO-FUN-01 base) | H120: [EST] calibration | I120: =INDEX(C120:E120,$C$4) -> 2.417461 | J120: rate
A121: A-GRO-BUD-01 | B121: Paid media budget, month 1 (Nov-26) | C121: 10000 | D121: 15000 | E121: 15000 | F121: ₹ | G121: growth_marketing_strategy.md §6.4/§10; marketing_channel_plan.md §3.2 (Mar+ only if spend gates green) | H121: [EST] | I121: =INDEX(C121:E121,$C$4) -> 15000 | J121: plan
A122: A-GRO-BUD-02 | B122: Paid media budget, month 2 (Dec-26) | C122: 25000 | D122: 40000 | E122: 50000 | F122: ₹ | G122: growth_marketing_strategy.md §6.4/§10; marketing_channel_plan.md §3.2 (Mar+ only if spend gates green) | H122: [EST] | I122: =INDEX(C122:E122,$C$4) -> 40000 | J122: plan
A123: A-GRO-BUD-03 | B123: Paid media budget, month 3 (Jan-27) | C123: 30000 | D123: 50000 | E123: 60000 | F123: ₹ | G123: growth_marketing_strategy.md §6.4/§10; marketing_channel_plan.md §3.2 (Mar+ only if spend gates green) | H123: [EST] | I123: =INDEX(C123:E123,$C$4) -> 50000 | J123: plan
A124: A-GRO-BUD-04 | B124: Paid media budget, month 4 (Feb-27) | C124: 35000 | D124: 60000 | E124: 70000 | F124: ₹ | G124: growth_marketing_strategy.md §6.4/§10; marketing_channel_plan.md §3.2 (Mar+ only if spend gates green) | H124: [EST] | I124: =INDEX(C124:E124,$C$4) -> 60000 | J124: plan
A125: A-GRO-BUD-05 | B125: Paid media budget, month 5 (Mar-27) | C125: 40000 | D125: 80000 | E125: 120000 | F125: ₹ | G125: growth_marketing_strategy.md §6.4/§10; marketing_channel_plan.md §3.2 (Mar+ only if spend gates green) | H125: [EST] | I125: =INDEX(C125:E125,$C$4) -> 80000 | J125: plan
A126: A-GRO-BUD-06 | B126: Paid media budget, month 6 (Apr-27) | C126: 40000 | D126: 90000 | E126: 170000 | F126: ₹ | G126: growth_marketing_strategy.md §6.4/§10; marketing_channel_plan.md §3.2 (Mar+ only if spend gates green) | H126: [EST] | I126: =INDEX(C126:E126,$C$4) -> 90000 | J126: plan
A127: A-GRO-BUD-07 | B127: Paid media budget, month 7 (May-27) | C127: 40000 | D127: 100000 | E127: 200000 | F127: ₹ | G127: growth_marketing_strategy.md §6.4/§10; marketing_channel_plan.md §3.2 (Mar+ only if spend gates green) | H127: [EST] | I127: =INDEX(C127:E127,$C$4) -> 100000 | J127: plan
A128: A-GRO-BUD-08 | B128: Paid media budget, month 8 (Jun-27) | C128: 40000 | D128: 100000 | E128: 200000 | F128: ₹ | G128: growth_marketing_strategy.md §6.4/§10; marketing_channel_plan.md §3.2 (Mar+ only if spend gates green) | H128: [EST] | I128: =INDEX(C128:E128,$C$4) -> 100000 | J128: plan
A129: A-GRO-BUD-09 | B129: Paid media budget, month 9 (Jul-27) | C129: 40000 | D129: 100000 | E129: 200000 | F129: ₹ | G129: growth_marketing_strategy.md §6.4/§10; marketing_channel_plan.md §3.2 (Mar+ only if spend gates green) | H129: [EST] | I129: =INDEX(C129:E129,$C$4) -> 100000 | J129: plan
A130: A-GRO-BUD-10 | B130: Paid media budget, month 10 (Aug-27) | C130: 40000 | D130: 100000 | E130: 200000 | F130: ₹ | G130: growth_marketing_strategy.md §6.4/§10; marketing_channel_plan.md §3.2 (Mar+ only if spend gates green) | H130: [EST] | I130: =INDEX(C130:E130,$C$4) -> 100000 | J130: plan
A131: A-GRO-BUD-11 | B131: Paid media budget, month 11 (Sep-27) | C131: 40000 | D131: 100000 | E131: 200000 | F131: ₹ | G131: growth_marketing_strategy.md §6.4/§10; marketing_channel_plan.md §3.2 (Mar+ only if spend gates green) | H131: [EST] | I131: =INDEX(C131:E131,$C$4) -> 100000 | J131: plan
A132: A-GRO-BUD-12 | B132: Paid media budget, month 12 (Oct-27) | C132: 40000 | D132: 100000 | E132: 200000 | F132: ₹ | G132: growth_marketing_strategy.md §6.4/§10; marketing_channel_plan.md §3.2 (Mar+ only if spend gates green) | H132: [EST] | I132: =INDEX(C132:E132,$C$4) -> 100000 | J132: plan
... A229: A-ECO-220a | B229: Batch slots per day, Y2 | C229: 2.5 | D229: 3 | E229: 3 | F229: slots | G229: Weekend / evening batches | H229: [HYP] | I229: =INDEX(C229:E229,$C$4) -> 3 | J229: plan
A230: A-ECO-220b | B230: Batch slots per day, Y3 | C230: 3 | D230: 3 | E230: 3 | F230: slots | H230: [HYP] | I230: =INDEX(C230:E230,$C$4) -> 3 | J230: plan
...

Sheet Unit_Economics
A1: Programme unit economics - per seat and per cohort (scenario = Assumptions!C3 selector)
A2: Ladder from positioning_and_segments.md §6 (Growth) with BM realised fees. Fees incl. GST as quoted; revenue ex-GST. Trainer cost is a standard cost (salary / slots / fill).
A4: Metric | B4: L1 Career Taster | C4: L1-S5 Self-makeup | D4: L2 Foundation | E4: L3 Pro - today's fee (CA-02, incl. kit) | F4: L3 Pro - after price step (A-BM-02) | G4: L3 Destination / hybrid | H4: L4 Masterclass | I4: L5 Pro Circle (per yr) | J4: Notes
A5: Duration (on-campus months; seat-months per student) | B5: =0.1 -> 0.1 | C5: =0.1 -> 0.1 | D5: =1 -> 1 | E5: =Assumptions!$I$103 -> 3 | F5: =Assumptions!$I$103 -> 3 | G5: =Assumptions!$I$104 -> 2.5 | H5: =0.07 -> 0.07 | I5: =0 -> 0
A6: Contact hours (indicative) | B6: =3 -> 3 | C6: =6 -> 6 | D6: =80 -> 80 | E6: =290 -> 290 | F6: =290 -> 290 | G6: =250 -> 250 | H6: =12 -> 12 | I6: =24 -> 24
A7: Batch cap (A-BM-01) / seats per session | B7: =12 -> 12 | C7: =12 -> 12 | D7: =12 -> 12 | E7: =12 -> 12 | F7: =12 -> 12 | G7: =12 -> 12 | H7: =14 -> 14 | I7: =0 -> 0
A8: Cohort fill used (A-ECO-47; masterclass x A-ECO-132) | B8: =Assumptions!$I$102 -> 10 | C8: =Assumptions!$I$102 -> 10 | D8: =Assumptions!$I$102 -> 10 | E8: =Assumptions!$I$102 -> 10 | F8: =Assumptions!$I$102 -> 10 | G8: =Assumptions!$I$102 -> 10 | H8: =14*Assumptions!$I$193 -> 11.9 | I8: =0 -> 0
A9: Fee incl. GST (as quoted) | B9: =Assumptions!$I$17 -> 999 | C9: =Assumptions!$I$22 -> 4999 | D9: =Assumptions!$I$18 -> 39900 | E9: =Assumptions!$I$10 -> 60000 | F9: =Assumptions!$I$20 -> 80000 | G9: =Assumptions!$I$20 -> 80000 | H9: =Assumptions!$I$21 -> 10000 | I9: =Assumptions!$I$23 -> 9999
A10: Revenue per seat ex-GST | B10: =B9/(1+Assumptions!$I$15*Assumptions!$I$16) -> 846.61017 | C10: =C9/(1+Assumptions!$I$15*Assumptions!$I$16) -> 4236.4407 | D10: =D9/(1+Assumptions!$I$15*Assumptions!$I$16) -> 33813.559 | E10: =E9/(1+Assumptions!$I$15*Assumptions!$I$16) -> 50847.458 | F10: =F9/(1+Assumptions!$I$15*Assumptions!$I$16) -> 67796.61 | G10: =G9/(1+Assumptions!$I$15*Assumptions!$I$16) -> 67796.61 | H10: =H9/(1+Assumptions!$I$15*Assumptions!$I$16) -> 8474.5763 | I10: =I9/(1+Assumptions!$I$15*Assumptions!$I$16) -> 8473.7288
A11: Kit cost borne by PNA | B11: =0 -> 0 | C11: =0 -> 0 | D11: =0 -> 0 | E11: =Assumptions!$I$14 -> 12000 | F11: =0 -> 0 | G11: =0 -> 0 | H11: =0 -> 0 | I11: =0 -> 0
A12: Consumables / models / delivery | B12: =Assumptions!$I$96 -> 250 | C12: =Assumptions!$I$95 -> 400 | D12: =Assumptions!$I$92 -> 2000 | E12: =Assumptions!$I$91 -> 6000 | F12: =Assumptions!$I$91 -> 6000 | G12: =Assumptions!$I$93 -> 7500 | H12: =Assumptions!$I$94 -> 1000 | I12: =Assumptions!$I$97 -> 2000
A13: Trainer + assistant cost per batch (standard: salary x months / slots) | B13: =0 -> 0 | C13: =0 -> 0 | D13: =(Assumptions!$I$99+Assumptions!$I$100)/Assumptions!$I$101*D5 -> 28000 | E13: =(Assumptions!$I$99+Assumptions!$I$100)/Assumptions!$I$101*E5 -> 84000 | F13: =(Assumptions!$I$99+Assumptions!$I$100)/Assumptions!$I$101*F5 -> 84000 | G13: =(Assumptions!$I$99+Assumptions!$I$100)/Assumptions!$I$101*G5 -> 70000 | H13: =0 -> 0 | I13: =0 -> 0
A14: Trainer cost per student (batch cost / fill) | B14: =IFERROR(B13/B8,0) -> 0 | C14: =IFERROR(C13/C8,0) -> 0 | D14: =IFERROR(D13/D8,0) -> 2800 | E14: =IFERROR(E13/E8,0) -> 8400 | F14: =IFERROR(F13/F8,0) -> 8400 | G14: =IFERROR(G13/G8,0) -> 7000 | H14: =IFERROR(H13/H8,0) -> 0 | I14: =IFERROR(I13/I8,0) -> 0
A15: Payment gateway + EMI subvention | B15: =B9*Assumptions!$I$76 -> 19.98 | C15: =C9*Assumptions!$I$76 -> 99.98 | D15: =D9*Assumptions!$I$76 -> 798 | E15: =E9*(Assumptions!$I$76+Assumptions!$I$70*Assumptions!$I$71) -> 2250 | F15: =F9*(Assumptions!$I$76+Assumptions!$I$70*Assumptions!$I$71) -> 3000 | G15: =G9*(Assumptions!$I$76+Assumptions!$I$70*Assumptions!$I$71) -> 3000 | H15: =H9*Assumptions!$I$76 -> 200 | I15: =I9*Assumptions!$I$76 -> 199.98
A16: Contribution per seat before CAC | B16: =B10-B11-B12-B14-B15 -> 576.63017 | C16: =C10-C11-C12-C14-C15 -> 3736.4607 | D16: =D10-D11-D12-D14-D15 -> 28215.559 | E16: =E10-E11-E12-E14-E15 -> 22197.458 | F16: =F10-F11-F12-F14-F15 -> 50396.61 | G16: =G10-G11-G12-G14-G15 -> 50296.61 | H16: =H10-H11-H12-H14-H15 -> 7274.5763 | I16: =I10-I11-I12-I14-I15 -> 6273.7488
A17: Contribution margin % | B17: =IFERROR(B16/B10,0) -> 0.6811047 | C17: =IFERROR(C16/C10,0) -> 0.88198112 | D17: =IFERROR(D16/D10,0) -> 0.83444511 | E17: =IFERROR(E16/E10,0) -> 0.43655 | F17: =IFERROR(F16/F10,0) -> 0.74335 | G17: =IFERROR(G16/G10,0) -> 0.741875 | H17: =IFERROR(H16/H10,0) -> 0.8584 | I17: =IFERROR(I16/I10,0) -> 0.7403764
A18: Acquisition cost per seat (career: effective paid CAC x paid share + referral reward share; L4/L1-S5: funnel media per seat) | B18: =Assumptions!$I$35 -> 400 | C18: =Assumptions!$I$118 -> 706 | D18: =Assumptions!$I$115*Assumptions!$I$120*(Assumptions!$I$27+Assumptions!$I$28+Assumptions!$I$31)+Assumptions!$I$198*Assumptions!$I$69 -> 7600 | E18: =Assumptions!$I$115*Assumptions!$I$120*(Assumptions!$I$27+Assumptions!$I$28+Assumptions!$I$31)+Assumptions!$I$198*Assumptions!$I$69 -> 7600 | F18: =Assumptions!$I$115*Assumptions!$I$120*(Assumptions!$I$27+Assumptions!$I$28+Assumptions!$I$31)+Assumptions!$I$198*Assumptions!$I$69 -> 7600 | G18: =Assumptions!$I$115*Assumptions!$I$120*(Assumptions!$I$27+Assumptions!$I$28+Assumptions!$I$31)+Assumptions!$I$198*Assumptions!$I$69 -> 7600 | H18: =Assumptions!$I$117 -> 300 | I18: =0 -> 0
A19: Contribution per seat after CAC | B19: =B16-B18 -> 176.63017 | C19: =C16-C18 -> 3030.4607 | D19: =D16-D18 -> 20615.559 | E19: =E16-E18 -> 14597.458 | F19: =F16-F18 -> 42796.61 | G19: =G16-G18 -> 42696.61 | H19: =H16-H18 -> 6974.5763 | I19: =I16-I18 -> 6273.7488
A20: Occupancy cost per seat (today's space: rent + utilities / seat-months) | B20: =(Assumptions!$I$179+Assumptions!$I$180)/(Assumptions!$I$171*Assumptions!$I$172)*B5 -> 281.25 | C20: =(Assumptions!$I$179+Assumptions!$I$180)/(Assumptions!$I$171*Assumptions!$I$172)*C5 -> 281.25 | D20: =(Assumptions!$I$179+Assumptions!$I$180)/(Assumptions!$I$171*Assumptions!$I$172)*D5 -> 2812.5 | E20: =(Assumptions!$I$179+Assumptions!$I$180)/(Assumptions!$I$171*Assumptions!$I$172)*E5 -> 8437.5 | F20: =(Assumptions!$I$179+Assumptions!$I$180)/(Assumptions!$I$171*Assumptions!$I$172)*F5 -> 8437.5 | G20: =(Assumptions!$I$179+Assumptions!$I$180)/(Assumptions!$I$171*Assumptions!$I$172)*G5 -> 7031.25 | H20: =(Assumptions!$I$179+Assumptions!$I$180)/(Assumptions!$I$171*Assumptions!$I$172)*H5 -> 196.875 | I20: =(Assumptions!$I$179+Assumptions!$I$180)/(Assumptions!$I$171*Assumptions!$I$172)*I5 -> 0
A21: Cohort fixed cost (trainer batch cost + occupancy x batch cap) | B21: =B13+B20*B7 -> 3375 | C21: =C13+C20*C7 -> 3375 | D21: =D13+D20*D7 -> 61750 | E21: =E13+E20*E7 -> 185250 | F21: =F13+F20*F7 -> 185250 | G21: =G13+G20*G7 -> 154375 | H21: =H13+H20*H7 -> 2756.25 | I21: =I13+I20*I7 -> 0
A22: Variable cost per seat (kit + consumables + payment + CAC) | B22: =B11+B12+B15+B18 -> 669.98 | C22: =C11+C12+C15+C18 -> 1205.98 | D22: =D11+D12+D15+D18 -> 10398 | E22: =E11+E12+E15+E18 -> 27850 | F22: =F11+F12+F15+F18 -> 16600 | G22: =G11+G12+G15+G18 -> 18100 | H22: =H11+H12+H15+H18 -> 1500 | I22: =I11+I12+I15+I18 -> 2199.98
A23: Breakeven students per cohort | B23: =IFERROR(B21/(B10-B22),0) -> 19.107721 | C23: =IFERROR(C21/(C10-C22),0) -> 1.1136921 | D23: =IFERROR(D21/(D10-D22),0) -> 2.6371354 | E23: =IFERROR(E21/(E10-E22),0) -> 8.0552382 | F23: =IFERROR(F21/(F10-F22),0) -> 3.6184036 | G23: =IFERROR(G21/(G10-G22),0) -> 3.1063487 | H23: =IFERROR(H21/(H10-H22),0) -> 0.3951853 | I23: =IFERROR(I21/(I10-I22),0) -> 0
A24: Breakeven fill % of batch cap (BM M1) | B24: =IFERROR(B23/B7,0) -> 1.5923101 | C24: =IFERROR(C23/C7,0) -> 0.092807672 | D24: =IFERROR(D23/D7,0) -> 0.21976128 | E24: =IFERROR(E23/E7,0) -> 0.67126985 | F24: =IFERROR(F23/F7,0) -> 0.30153364 | G24: =IFERROR(G23/G7,0) -> 0.25886239 | H24: =IFERROR(H23/H7,0) -> 0.028227521 | I24: =IFERROR(I23/I7,0) -> 0
A25: Cohort contribution at 10 students (after CAC, trainer, occupancy) | B25: =10*(B10-B22)-B21 -> -1608.6983 | C25: =10*(C10-C22)-C21 -> 26929.607 | D25: =10*(D10-D22)-D21 -> 172405.59 | E25: =10*(E10-E22)-E21 -> 44724.576 | F25: =10*(F10-F22)-F21 -> 326716.1 | G25: =10*(G10-G22)-G21 -> 342591.1 | H25: =10*(H10-H22)-H21 -> 66989.513 | I25: =10*(I10-I22)-I21 -> 62737.488
A26: Cohort contribution at 12 students | B26: =12*(B10-B22)-B21 -> -1255.438 | C26: =12*(C10-C22)-C21 -> 32990.528 | D26: =12*(D10-D22)-D21 -> 219236.71 | E26: =12*(E10-E22)-E21 -> 90719.492 | F26: =12*(F10-F22)-F21 -> 429109.32 | G26: =12*(G10-G22)-G21 -> 441984.32 | H26: =12*(H10-H22)-H21 -> 80938.665 | I26: =12*(I10-I22)-I21 -> 75284.986
A27: Cohort contribution at 14 students (cap raised; quality risk) | B27: =14*(B10-B22)-B21 -> -902.17763 | C27: =14*(C10-C22)-C21 -> 39051.449 | D27: =14*(D10-D22)-D21 -> 266067.83 | E27: =14*(E10-E22)-E21 -> 136714.41 | F27: =14*(F10-F22)-F21 -> 531502.54 | G27: =14*(G10-G22)-G21 -> 541377.54 | H27: =14*(H10-H22)-H21 -> 94887.818 | I27: =14*(I10-I22)-I21 -> 87832.483
A28: Batches per year per slot (12 / duration) | B28: =IFERROR(12/B5,0) -> 120 | C28: =IFERROR(12/C5,0) -> 120 | D28: =IFERROR(12/D5,0) -> 12 | E28: =IFERROR(12/E5,0) -> 4 | F28: =IFERROR(12/F5,0) -> 4 | G28: =IFERROR(12/G5,0) -> 4.8 | H28: =IFERROR(12/H5,0) -> 171.42857 | I28: =IFERROR(12/I5,0) -> 0
A30: Today's illustrative baseline (CA-01 x CA-02 mix) - NOT actual revenue; founder data pull (V1) to replace
A31: Students per year (CA-01) | B31: =Assumptions!$I$9 -> 50
A32: Career share (A-ECO-101) | B32: =Assumptions!$I$12 -> 0.6
A33: Career students | B33: =B31*B32 -> 30
A34: Short-course students | B34: =B31-B33 -> 20
A35: Illustrative revenue incl. GST (career x CA-02 + short x A-ECO-102) | B35: =B33*Assumptions!$I$10+B34*Assumptions!$I$13 -> 1960000
A36: Illustrative revenue ex-GST | B36: =B35/(1+Assumptions!$I$15*Assumptions!$I$16) -> 1661016.9
A37: Illustrative contribution (kit + consumables + payment) | B37: =B36-B33*(Assumptions!$I$14+Assumptions!$I$91)-B34*Assumptions!$I$94-B35*Assumptions!$I$76 -> 1061816.9
A38: Less academy occupancy share x 12 | B38: =-12*(Assumptions!$I$179+Assumptions!$I$180) -> -540000
A39: Illustrative academy surplus before founder's time (NOT actual profit) | B39: =B37+B38 -> 521816.95
A41: BM's '~₹0.3 crore today' is this same CA-01 x CA-02 arithmetic (50 x ₹60k), an estimate, not PNA's reported revenue.

Sheet 3yr_Scenarios
A1: Directional 3-year scenarios (₹ lakh, ex-GST) - Year 1 = 12-month outlook; Years 2-3 driver-based
A2: Layers: flagship (tricity + regional offline), destination/hybrid, CPD (masterclasses + Pro Circle), online, adjacents, and a partner-hosted satellite only if gate G3a is met (Aggressive Y3).
A4: Line (₹ lakh unless stated) | B4: Conservative Y1 | C4: Conservative Y2 | D4: Conservative Y3 | E4: Base Y1 | F4: Base Y2 | G4: Base Y3 | H4: Aggressive Y1 | I4: Aggressive Y2 | J4: Aggressive Y3 | K4: Basis
A5: Volumes
A6: Career enrolments, flagship (L2 + L3 new students) | B6: =Outlook_Conservative!O31 -> 30.376401 | C6: =2*SUM(Outlook_Conservative!I31:N31)/(SUM(Outlook_Conservative!I9:N9)/6)*(1+INDEX(Assumptions!$C$199:$E$199,1)) -> 38.989295 | D6: =C6*(1+INDEX(Assumptions!$C$200:$E$200,1)) -> 40.93876 | E6: =Outlook_Base!O31 -> 89.450184 | F6: =2*SUM(Outlook_Base!I31:N31)/(SUM(Outlook_Base!I9:N9)/6)*(1+INDEX(Assumptions!$C$199:$E$199,2)) -> 121.91883 | G6: =F6*(1+INDEX(Assumptions!$C$200:$E$200,2)) -> 134.11072 | H6: =Outlook_Aggressive!O31 -> 123.22992 | I6: =2*SUM(Outlook_Aggressive!I31:N31)/(SUM(Outlook_Aggressive!I9:N9)/6)*(1+INDEX(Assumptions!$C$199:$E$199,3)) -> 161.42344 | J6: =I6*(1+INDEX(Assumptions!$C$200:$E$200,3)) -> 180.79425 | K6: Y2 = 2 x Y1 H2 run-rate, de-seasonalised (May-Oct index), x (1+A-ECO-201); Y3 x (1+A-ECO-202); capacity-capped below
A7: L3 share of career enrolments | B7: =INDEX(Assumptions!$C$26:$E$26,1) -> 0.5 | C7: =INDEX(Assumptions!$C$26:$E$26,1) -> 0.5 | D7: =INDEX(Assumptions!$C$26:$E$26,1) -> 0.5 | E7: =INDEX(Assumptions!$C$26:$E$26,2) -> 0.6 | F7: =INDEX(Assumptions!$C$26:$E$26,2) -> 0.6 | G7: =INDEX(Assumptions!$C$26:$E$26,2) -> 0.6 | H7: =INDEX(Assumptions!$C$26:$E$26,3) -> 0.7 | I7: =INDEX(Assumptions!$C$26:$E$26,3) -> 0.7 | J7: =INDEX(Assumptions!$C$26:$E$26,3) -> 0.7
A8: Out-of-town share of career enrolments | B8: =INDEX(Assumptions!$C$74:$E$74,1) -> 0.15 | C8: =INDEX(Assumptions!$C$201:$E$201,1) -> 0.15 | D8: =INDEX(Assumptions!$C$202:$E$202,1) -> 0.18 | E8: =INDEX(Assumptions!$C$74:$E$74,2) -> 0.25 | F8: =INDEX(Assumptions!$C$201:$E$201,2) -> 0.25 | G8: =INDEX(Assumptions!$C$202:$E$202,2) -> 0.3 | H8: =INDEX(Assumptions!$C$74:$E$74,3) -> 0.35 | I8: =INDEX(Assumptions!$C$201:$E$201,3) -> 0.35 | J8: =INDEX(Assumptions!$C$202:$E$202,3) -> 0.4
A9: Incremental destination/hybrid regional students (G2 engine) | B9: =Outlook_Conservative!O28*0 -> 0 | C9: =INDEX(Assumptions!$C$203:$E$203,1) -> 0 | D9: =INDEX(Assumptions!$C$204:$E$204,1) -> 8 | E9: =Outlook_Base!O28*0 -> 0 | F9: =INDEX(Assumptions!$C$203:$E$203,2) -> 15 | G9: =INDEX(Assumptions!$C$204:$E$204,2) -> 35 | H9: =Outlook_Aggressive!O28*0 -> 0 | I9: =INDEX(Assumptions!$C$203:$E$203,3) -> 30 | J9: =INDEX(Assumptions!$C$204:$E$204,3) -> 60 | K9: Y1 destination-format students are inside career enrolments
A10: L2 -> L3 upgrades | B10: =Outlook_Conservative!O30 -> 3.4102516 | C10: =C6*(1-INDEX(Assumptions!$C$26:$E$26,1))*INDEX(Assumptions!$C$89:$E$89,1) -> 4.8736619 | D10: =D6*(1-INDEX(Assumptions!$C$26:$E$26,1))*INDEX(Assumptions!$C$89:$E$89,1) -> 5.117345 | E10: =Outlook_Base!O30 -> 8.6225776 | F10: =F6*(1-INDEX(Assumptions!$C$26:$E$26,2))*INDEX(Assumptions!$C$89:$E$89,2) -> 14.63026 | G10: =G6*(1-INDEX(Assumptions!$C$26:$E$26,2))*INDEX(Assumptions!$C$89:$E$89,2) -> 16.093286 | H10: =Outlook_Aggressive!O30 -> 11.079757 | I10: =I6*(1-INDEX(Assumptions!$C$26:$E$26,3))*INDEX(Assumptions!$C$89:$E$89,3) -> 19.370813 | J10: =J6*(1-INDEX(Assumptions!$C$26:$E$26,3))*INDEX(Assumptions!$C$89:$E$89,3) -> 21.69531
A11: Stations | B11: =Outlook_Conservative!N20 -> 8 | C11: =INDEX(Assumptions!$C$231:$E$231,1) -> 8 | D11: =INDEX(Assumptions!$C$232:$E$232,1) -> 10 | E11: =Outlook_Base!N20 -> 12 | F11: =INDEX(Assumptions!$C$231:$E$231,2) -> 12 | G11: =INDEX(Assumptions!$C$232:$E$232,2) -> 14 | H11: =Outlook_Aggressive!N20 -> 16 | I11: =INDEX(Assumptions!$C$231:$E$231,3) -> 16 | J11: =INDEX(Assumptions!$C$232:$E$232,3) -> 18
A12: Batch slots per day | B12: =Outlook_Conservative!N21 -> 2 | C12: =INDEX(Assumptions!$C$229:$E$229,1) -> 2.5 | D12: =INDEX(Assumptions!$C$230:$E$230,1) -> 3 | E12: =Outlook_Base!N21 -> 2.5 | F12: =INDEX(Assumptions!$C$229:$E$229,2) -> 3 | G12: =INDEX(Assumptions!$C$230:$E$230,2) -> 3 | H12: =Outlook_Aggressive!N21 -> 2.5 | I12: =INDEX(Assumptions!$C$229:$E$229,3) -> 3 | J12: =INDEX(Assumptions!$C$230:$E$230,3) -> 3
A13: Usable seat-months per year | B13: =B11*B12*12*INDEX(Assumptions!$C$178:$E$178,1) -> 172.8 | C13: =C11*C12*12*INDEX(Assumptions!$C$178:$E$178,1) -> 216 | D13: =D11*D12*12*INDEX(Assumptions!$C$178:$E$178,1) -> 324 | E13: =E11*E12*12*INDEX(Assumptions!$C$178:$E$178,2) -> 324 | F13: =F11*F12*12*INDEX(Assumptions!$C$178:$E$178,2) -> 388.8 | G13: =G11*G12*12*INDEX(Assumptions!$C$178:$E$178,2) -> 453.6 | H13: =H11*H12*12*INDEX(Assumptions!$C$178:$E$178,3) -> 432 | I13: =I11*I12*12*INDEX(Assumptions!$C$178:$E$178,3) -> 518.4 | J13: =J11*J12*12*INDEX(Assumptions!$C$178:$E$178,3) -> 583.2
A14: Seat-months needed (L3 x3, L2 x1, upgrades x3, destination x2.5) | B14: =Outlook_Conservative!O33*12 -> 65.026859 | C14: =C6*(C7*INDEX(Assumptions!$C$103:$E$103,1)+(1-C7))+C10*INDEX(Assumptions!$C$103:$E$103,1)+C9*INDEX(Assumptions!$C$104:$E$104,1) -> 92.599576 | D14: =D6*(D7*INDEX(Assumptions!$C$103:$E$103,1)+(1-D7))+D10*INDEX(Assumptions!$C$103:$E$103,1)+D9*INDEX(Assumptions!$C$104:$E$104,1) -> 117.22955 | E14: =Outlook_Base!O33*12 -> 200.9605 | F14: =F6*(F7*INDEX(Assumptions!$C$103:$E$103,2)+(1-F7))+F10*INDEX(Assumptions!$C$103:$E$103,2)+F9*INDEX(Assumptions!$C$104:$E$104,2) -> 349.61221 | G14: =G6*(G7*INDEX(Assumptions!$C$103:$E$103,2)+(1-G7))+G10*INDEX(Assumptions!$C$103:$E$103,2)+G9*INDEX(Assumptions!$C$104:$E$104,2) -> 430.82343 | H14: =Outlook_Aggressive!O33*12 -> 294.49261 | I14: =I6*(I7*INDEX(Assumptions!$C$103:$E$103,3)+(1-I7))+I10*INDEX(Assumptions!$C$103:$E$103,3)+I9*INDEX(Assumptions!$C$104:$E$104,3) -> 520.5287 | J14: =J6*(J7*INDEX(Assumptions!$C$103:$E$103,3)+(1-J7))+J10*INDEX(Assumptions!$C$103:$E$103,3)+J9*INDEX(Assumptions!$C$104:$E$104,3) -> 648.99214
A15: Capacity factor (share of planned volume that fits) | B15: =1 -> 1 | C15: =MIN(1,C13/C14) -> 1 | D15: =MIN(1,D13/D14) -> 1 | E15: =1 -> 1 | F15: =MIN(1,F13/F14) -> 1 | G15: =MIN(1,G13/G14) -> 1 | H15: =1 -> 1 | I15: =MIN(1,I13/I14) -> 0.99591051 | J15: =MIN(1,J13/J14) -> 0.89862413
A16: Seat utilisation | B16: =Outlook_Conservative!N34 -> 0.4834982 | C16: =MIN(1,C14/(C11*C12*12)) -> 0.38583156 | D16: =MIN(1,D14/(D11*D12*12)) -> 0.32563765 | E16: =Outlook_Base!N34 -> 0.84101366 | F16: =MIN(1,F14/(F11*F12*12)) -> 0.80928753 | G16: =MIN(1,G14/(G11*G12*12)) -> 0.8548084 | H16: =Outlook_Aggressive!N34 -> 0.9 | I16: =MIN(1,I14/(I11*I12*12)) -> 0.90369565 | J16: =MIN(1,J14/(J11*J12*12)) -> 1
A17: Career enrolments delivered (after capacity) | B17: =B6*B15 -> 30.376401 | C17: =C6*C15 -> 38.989295 | D17: =D6*D15 -> 40.93876 | E17: =E6*E15 -> 89.450184 | F17: =F6*F15 -> 121.91883 | G17: =G6*G15 -> 134.11072 | H17: =H6*H15 -> 123.22992 | I17: =I6*I15 -> 160.7633 | J17: =J6*J15 -> 162.46608
A18: Destination/hybrid incremental students delivered | B18: =B9*B15 -> 0 | C18: =C9*C15 -> 0 | D18: =D9*D15 -> 8 | E18: =E9*E15 -> 0 | F18: =F9*F15 -> 15 | G18: =G9*G15 -> 35 | H18: =H9*H15 -> 0 | I18: =I9*I15 -> 29.877315 | J18: =J9*J15 -> 53.917448
A19: Masterclass seats | B19: =Outlook_Conservative!O37 -> 67.5 | C19: =INDEX(Assumptions!$C$205:$E$205,1) -> 110 | D19: =INDEX(Assumptions!$C$206:$E$206,1) -> 130 | E19: =Outlook_Base!O37 -> 153 | F19: =INDEX(Assumptions!$C$205:$E$205,2) -> 220 | G19: =INDEX(Assumptions!$C$206:$E$206,2) -> 280 | H19: =Outlook_Aggressive!O37 -> 202.5 | I19: =INDEX(Assumptions!$C$205:$E$205,3) -> 330 | J19: =INDEX(Assumptions!$C$206:$E$206,3) -> 420
A20: Self-makeup seats | B20: =Outlook_Conservative!O38 -> 106.66667 | C20: =INDEX(Assumptions!$C$207:$E$207,1) -> 110 | D20: =INDEX(Assumptions!$C$208:$E$208,1) -> 120 | E20: =Outlook_Base!O38 -> 160 | F20: =INDEX(Assumptions!$C$207:$E$207,2) -> 170 | G20: =INDEX(Assumptions!$C$208:$E$208,2) -> 190 | H20: =Outlook_Aggressive!O38 -> 234.66667 | I20: =INDEX(Assumptions!$C$207:$E$207,3) -> 250 | J20: =INDEX(Assumptions!$C$208:$E$208,3) -> 280
A21: Pop-up events | B21: =Outlook_Conservative!O40 -> 0 | C21: =INDEX(Assumptions!$C$209:$E$209,1) -> 0 | D21: =INDEX(Assumptions!$C$210:$E$210,1) -> 2 | E21: =Outlook_Base!O40 -> 2 | F21: =INDEX(Assumptions!$C$209:$E$209,2) -> 6 | G21: =INDEX(Assumptions!$C$210:$E$210,2) -> 12 | H21: =Outlook_Aggressive!O40 -> 7 | I21: =INDEX(Assumptions!$C$209:$E$209,3) -> 12 | J21: =INDEX(Assumptions!$C$210:$E$210,3) -> 16
A22: Online short-course buyers | B22: =0 -> 0 | C22: =INDEX(Assumptions!$C$211:$E$211,1) -> 0 | D22: =INDEX(Assumptions!$C$212:$E$212,1) -> 150 | E22: =0 -> 0 | F22: =INDEX(Assumptions!$C$211:$E$211,2) -> 300 | G22: =INDEX(Assumptions!$C$212:$E$212,2) -> 900 | H22: =0 -> 0 | I22: =INDEX(Assumptions!$C$211:$E$211,3) -> 800 | J22: =INDEX(Assumptions!$C$212:$E$212,3) -> 2000
A23: Pro Circle paid members (graduates after free year + S3 buyers) | B23: =Outlook_Conservative!O42 -> 2.3625 | C23: =B17*B7*INDEX(Assumptions!$C$67:$E$67,1)*INDEX(Assumptions!$C$72:$E$72,1)+C19*0.7*INDEX(Assumptions!$C$73:$E$73,1) -> 6.4319941 | D23: =C17*C7*INDEX(Assumptions!$C$67:$E$67,1)*INDEX(Assumptions!$C$72:$E$72,1)+D19*0.7*INDEX(Assumptions!$C$73:$E$73,1) -> 7.8640901 | E23: =Outlook_Base!O42 -> 10.71 | F23: =E17*E7*INDEX(Assumptions!$C$67:$E$67,2)*INDEX(Assumptions!$C$72:$E$72,2)+F19*0.7*INDEX(Assumptions!$C$73:$E$73,2) -> 29.89093 | G23: =F17*F7*INDEX(Assumptions!$C$67:$E$67,2)*INDEX(Assumptions!$C$72:$E$72,2)+G19*0.7*INDEX(Assumptions!$C$73:$E$73,2) -> 39.350851 | H23: =Outlook_Aggressive!O42 -> 28.35 | I23: =H17*H7*INDEX(Assumptions!$C$67:$E$67,3)*INDEX(Assumptions!$C$72:$E$72,3)+I19*0.7*INDEX(Assumptions!$C$73:$E$73,3) -> 83.076554 | J23: =I17*I7*INDEX(Assumptions!$C$67:$E$67,3)*INDEX(Assumptions!$C$72:$E$72,3)+J19*0.7*INDEX(Assumptions!$C$73:$E$73,3) -> 106.90842
A24: Partner-hosted satellite students (only if G3a met) | B24: =0 -> 0 | C24: =0 -> 0 | D24: =INDEX(Assumptions!$C$222:$E$222,1) -> 0 | E24: =0 -> 0 | F24: =0 -> 0 | G24: =INDEX(Assumptions!$C$222:$E$222,2) -> 0 | H24: =0 -> 0 | I24: =0 -> 0 | J24: =INDEX(Assumptions!$C$222:$E$222,3) -> 30
A25: Founder share of contact hours | B25: =Outlook_Conservative!N11 -> 0.4 | C25: =INDEX(Assumptions!$C$159:$E$159,1) -> 0.2 | D25: =INDEX(Assumptions!$C$160:$E$160,1) -> 0.12 | E25: =Outlook_Base!N11 -> 0.3 | F25: =INDEX(Assumptions!$C$159:$E$159,2) -> 0.15 | G25: =INDEX(Assumptions!$C$160:$E$160,2) -> 0.1 | H25: =Outlook_Aggressive!N11 -> 0.25 | I25: =INDEX(Assumptions!$C$159:$E$159,3) -> 0.12 | J25: =INDEX(Assumptions!$C$160:$E$160,3) -> 0.08
A26: Prices (incl. GST)
A27: L3 / destination realised fee | B27: =Outlook_Conservative!N44 -> 65000 | C27: =INDEX(Assumptions!$C$20:$E$20,1) -> 65000 | D27: =C27*(1+INDEX(Assumptions!$C$226:$E$226,1)) -> 68250 | E27: =Outlook_Base!N44 -> 80000 | F27: =INDEX(Assumptions!$C$20:$E$20,2) -> 80000 | G27: =F27*(1+INDEX(Assumptions!$C$226:$E$226,2)) -> 84800 | H27: =Outlook_Aggressive!N44 -> 100000 | I27: =INDEX(Assumptions!$C$20:$E$20,3) -> 100000 | J27: =I27*(1+INDEX(Assumptions!$C$226:$E$226,3)) -> 108000
A28: L2 Foundation fee | B28: =INDEX(Assumptions!$C$18:$E$18,1) -> 30000 | C28: =INDEX(Assumptions!$C$18:$E$18,1) -> 30000 | D28: =INDEX(Assumptions!$C$18:$E$18,1)*(1+INDEX(Assumptions!$C$226:$E$226,1)) -> 31500 | E28: =INDEX(Assumptions!$C$18:$E$18,2) -> 39900 | F28: =INDEX(Assumptions!$C$18:$E$18,2) -> 39900 | G28: =INDEX(Assumptions!$C$18:$E$18,2)*(1+INDEX(Assumptions!$C$226:$E$226,2)) -> 42294 | H28: =INDEX(Assumptions!$C$18:$E$18,3) -> 45000 | I28: =INDEX(Assumptions!$C$18:$E$18,3) -> 45000 | J28: =INDEX(Assumptions!$C$18:$E$18,3)*(1+INDEX(Assumptions!$C$226:$E$226,3)) -> 48600
A29: Revenue (₹ lakh, ex-GST)
A30: Flagship career revenue - tricity-origin | B30: =(Outlook_Conservative!O58)*(1-INDEX(Assumptions!$C$74:$E$74,1))/100000 -> 9.0186151 | C30: =(C17*(C7*C27+(1-C7)*C28)+C10*C15*(C27-C28))/(1+INDEX(Assumptions!$C$15:$E$15,1)*INDEX(Assumptions!$C$16:$E$16,1))*(1-C8)/100000 -> 14.569358 | D30: =(D17*(D7*D27+(1-D7)*D28)+D10*D15*(D27-D28))/(1+INDEX(Assumptions!$C$15:$E$15,1)*INDEX(Assumptions!$C$16:$E$16,1))*(1-D8)/100000 -> 15.495798 | E30: =(Outlook_Base!O58)*(1-INDEX(Assumptions!$C$74:$E$74,2))/100000 -> 36.457657 | F30: =(F17*(F7*F27+(1-F7)*F28)+F10*F15*(F27-F28))/(1+INDEX(Assumptions!$C$15:$E$15,2)*INDEX(Assumptions!$C$16:$E$16,2))*(1-F8)/100000 -> 53.291962 | G30: =(G17*(G7*G27+(1-G7)*G28)+G10*G15*(G27-G28))/(1+INDEX(Assumptions!$C$15:$E$15,2)*INDEX(Assumptions!$C$16:$E$16,2))*(1-G8)/100000 -> 57.995866 | H30: =(Outlook_Aggressive!O58)*(1-INDEX(Assumptions!$C$74:$E$74,3))/100000 -> 58.139093 | I30: =(I17*(I7*I27+(1-I7)*I28)+I10*I15*(I27-I28))/(1+INDEX(Assumptions!$C$15:$E$15,3)*INDEX(Assumptions!$C$16:$E$16,3))*(1-I8)/100000 -> 79.789006 | J30: =(J17*(J7*J27+(1-J7)*J28)+J10*J15*(J27-J28))/(1+INDEX(Assumptions!$C$15:$E$15,3)*INDEX(Assumptions!$C$16:$E$16,3))*(1-J8)/100000 -> 80.386013 | K30: career revenue x (1 - out-of-town share)
A31: Flagship career revenue - out-of-town (regional destination, offline) | B31: =(Outlook_Conservative!O58)*INDEX(Assumptions!$C$74:$E$74,1)/100000 -> 1.5915203 | C31: =(C17*(C7*C27+(1-C7)*C28)+C10*C15*(C27-C28))/(1+INDEX(Assumptions!$C$15:$E$15,1)*INDEX(Assumptions!$C$16:$E$16,1))*C8/100000 -> 2.5710631 | D31: =(D17*(D7*D27+(1-D7)*D28)+D10*D15*(D27-D28))/(1+INDEX(Assumptions!$C$15:$E$15,1)*INDEX(Assumptions!$C$16:$E$16,1))*D8/100000 -> 3.4015165 | E31: =(Outlook_Base!O58)*INDEX(Assumptions!$C$74:$E$74,2)/100000 -> 12.152552 | F31: =(F17*(F7*F27+(1-F7)*F28)+F10*F15*(F27-F28))/(1+INDEX(Assumptions!$C$15:$E$15,2)*INDEX(Assumptions!$C$16:$E$16,2))*F8/100000 -> 17.763987 | G31: =(G17*(G7*G27+(1-G7)*G28)+G10*G15*(G27-G28))/(1+INDEX(Assumptions!$C$15:$E$15,2)*INDEX(Assumptions!$C$16:$E$16,2))*G8/100000 -> 24.855371 | H31: =(Outlook_Aggressive!O58)*INDEX(Assumptions!$C$74:$E$74,3)/100000 -> 31.305665 | I31: =(I17*(I7*I27+(1-I7)*I28)+I10*I15*(I27-I28))/(1+INDEX(Assumptions!$C$15:$E$15,3)*INDEX(Assumptions!$C$16:$E$16,3))*I8/100000 -> 42.963311 | J31: =(J17*(J7*J27+(1-J7)*J28)+J10*J15*(J27-J28))/(1+INDEX(Assumptions!$C$15:$E$15,3)*INDEX(Assumptions!$C$16:$E$16,3))*J8/100000 -> 53.590676
A32: Destination/hybrid incremental regional students | B32: =0 -> 0 | C32: =C18*C27/(1+INDEX(Assumptions!$C$15:$E$15,1)*INDEX(Assumptions!$C$16:$E$16,1))/100000 -> 0 | D32: =D18*D27/(1+INDEX(Assumptions!$C$15:$E$15,1)*INDEX(Assumptions!$C$16:$E$16,1))/100000 -> 4.6271186 | E32: =0 -> 0 | F32: =F18*F27/(1+INDEX(Assumptions!$C$15:$E$15,2)*INDEX(Assumptions!$C$16:$E$16,2))/100000 -> 10.169492 | G32: =G18*G27/(1+INDEX(Assumptions!$C$15:$E$15,2)*INDEX(Assumptions!$C$16:$E$16,2))/100000 -> 25.152542 | H32: =0 -> 0 | I32: =I18*I27/(1+INDEX(Assumptions!$C$15:$E$15,3)*INDEX(Assumptions!$C$16:$E$16,3))/100000 -> 25.319759 | J32: =J18*J27/(1+INDEX(Assumptions!$C$15:$E$15,3)*INDEX(Assumptions!$C$16:$E$16,3))/100000 -> 49.348173
A33: Entry products: taster, self-makeup, pop-up tickets | B33: =(Outlook_Conservative!O51+Outlook_Conservative!O53+Outlook_Conservative!O54)/100000 -> 3.1147636 | C33: =(C20*INDEX(Assumptions!$C$22:$E$22,1)+C21*INDEX(Assumptions!$C$82:$E$82,1)*INDEX(Assumptions!$C$83:$E$83,1)+C17*INDEX(Assumptions!$C$31:$E$31,1)/(INDEX(Assumptions!$C$56:$E$56,1)*INDEX(Assumptions!$C$57:$E$57,1)*INDEX(Assumptions!$C$58:$E$58,1))*(1-INDEX(Assumptions!$C$56:$E$56,1)*INDEX(Assumptions!$C$57:$E$57,1)*INDEX(Assumptions!$C$58:$E$58,1))*INDEX(Assumptions!$C$17:$E$17,1))/(1+INDEX(Assumptions!$C$15:$E$15,1)*INDEX(Assumptions!$C$16:$E$16,1))/100000 -> 3.313747 | D33: =(D20*INDEX(Assumptions!$C$22:$E$22,1)+D21*INDEX(Assumptions!$C$82:$E$82,1)*INDEX(Assumptions!$C$83:$E$83,1)+D17*INDEX(Assumptions!$C$31:$E$31,1)/(INDEX(Assumptions!$C$56:$E$56,1)*INDEX(Assumptions!$C$57:$E$57,1)*INDEX(Assumptions!$C$58:$E$58,1))*(1-INDEX(Assumptions!$C$56:$E$56,1)*INDEX(Assumptions!$C$57:$E$57,1)*INDEX(Assumptions!$C$58:$E$58,1))*INDEX(Assumptions!$C$17:$E$17,1))/(1+INDEX(Assumptions!$C$15:$E$15,1)*INDEX(Assumptions!$C$16:$E$16,1))/100000 -> 4.0171462 | E33: =(Outlook_Base!O51+Outlook_Base!O53+Outlook_Base!O54)/100000 -> 8.2846181 | F33: =(F20*INDEX(Assumptions!$C$22:$E$22,2)+F21*INDEX(Assumptions!$C$82:$E$82,2)*INDEX(Assumptions!$C$83:$E$83,2)+F17*INDEX(Assumptions!$C$31:$E$31,2)/(INDEX(Assumptions!$C$56:$E$56,2)*INDEX(Assumptions!$C$57:$E$57,2)*INDEX(Assumptions!$C$58:$E$58,2))*(1-INDEX(Assumptions!$C$56:$E$56,2)*INDEX(Assumptions!$C$57:$E$57,2)*INDEX(Assumptions!$C$58:$E$58,2))*INDEX(Assumptions!$C$17:$E$17,2))/(1+INDEX(Assumptions!$C$15:$E$15,2)*INDEX(Assumptions!$C$16:$E$16,2))/100000 -> 10.506054 | G33: =(G20*INDEX(Assumptions!$C$22:$E$22,2)+G21*INDEX(Assumptions!$C$82:$E$82,2)*INDEX(Assumptions!$C$83:$E$83,2)+G17*INDEX(Assumptions!$C$31:$E$31,2)/(INDEX(Assumptions!$C$56:$E$56,2)*INDEX(Assumptions!$C$57:$E$57,2)*INDEX(Assumptions!$C$58:$E$58,2))*(1-INDEX(Assumptions!$C$56:$E$56,2)*INDEX(Assumptions!$C$57:$E$57,2)*INDEX(Assumptions!$C$58:$E$58,2))*INDEX(Assumptions!$C$17:$E$17,2))/(1+INDEX(Assumptions!$C$15:$E$15,2)*INDEX(Assumptions!$C$16:$E$16,2))/100000 -> 13.878898 | H33: =(Outlook_Aggressive!O51+Outlook_Aggressive!O53+Outlook_Aggressive!O54)/100000 -> 17.048573 | I33: =(I20*INDEX(Assumptions!$C$22:$E$22,3)+I21*INDEX(Assumptions!$C$82:$E$82,3)*INDEX(Assumptions!$C$83:$E$83,3)+I17*INDEX(Assumptions!$C$31:$E$31,3)/(INDEX(Assumptions!$C$56:$E$56,3)*INDEX(Assumptions!$C$57:$E$57,3)*INDEX(Assumptions!$C$58:$E$58,3))*(1-INDEX(Assumptions!$C$56:$E$56,3)*INDEX(Assumptions!$C$57:$E$57,3)*INDEX(Assumptions!$C$58:$E$58,3))*INDEX(Assumptions!$C$17:$E$17,3))/(1+INDEX(Assumptions!$C$15:$E$15,3)*INDEX(Assumptions!$C$16:$E$16,3))/100000 -> 20.488842 | J33: =(J20*INDEX(Assumptions!$C$22:$E$22,3)+J21*INDEX(Assumptions!$C$82:$E$82,3)*INDEX(Assumptions!$C$83:$E$83,3)+J17*INDEX(Assumptions!$C$31:$E$31,3)/(INDEX(Assumptions!$C$56:$E$56,3)*INDEX(Assumptions!$C$57:$E$57,3)*INDEX(Assumptions!$C$58:$E$58,3))*(1-INDEX(Assumptions!$C$56:$E$56,3)*INDEX(Assumptions!$C$57:$E$57,3)*INDEX(Assumptions!$C$58:$E$58,3))*INDEX(Assumptions!$C$17:$E$17,3))/(1+INDEX(Assumptions!$C$15:$E$15,3)*INDEX(Assumptions!$C$16:$E$16,3))/100000 -> 24.180494
A34: Working-artist CPD: L4 masterclasses + L5 Pro Circle | B34: =(Outlook_Conservative!O52+Outlook_Conservative!O55)/100000 -> 2.9602554 | C34: =(C19*INDEX(Assumptions!$C$21:$E$21,1)+C23*INDEX(Assumptions!$C$23:$E$23,1))/(1+INDEX(Assumptions!$C$15:$E$15,1)*INDEX(Assumptions!$C$16:$E$16,1))/100000 -> 4.9335046 | D34: =(D19*INDEX(Assumptions!$C$21:$E$21,1)+D23*INDEX(Assumptions!$C$23:$E$23,1))/(1+INDEX(Assumptions!$C$15:$E$15,1)*INDEX(Assumptions!$C$16:$E$16,1))/100000 -> 5.8416321 | E34: =(Outlook_Base!O52+Outlook_Base!O55)/100000 -> 13.873638 | F34: =(F19*INDEX(Assumptions!$C$21:$E$21,2)+F23*INDEX(Assumptions!$C$23:$E$23,2))/(1+INDEX(Assumptions!$C$15:$E$15,2)*INDEX(Assumptions!$C$16:$E$16,2))/100000 -> 21.176944 | G34: =(G19*INDEX(Assumptions!$C$21:$E$21,2)+G23*INDEX(Assumptions!$C$23:$E$23,2))/(1+INDEX(Assumptions!$C$15:$E$15,2)*INDEX(Assumptions!$C$16:$E$16,2))/100000 -> 27.063298 | H34: =(Outlook_Aggressive!O52+Outlook_Aggressive!O55)/100000 -> 27.028361 | I34: =(I19*INDEX(Assumptions!$C$21:$E$21,3)+I23*INDEX(Assumptions!$C$23:$E$23,3))/(1+INDEX(Assumptions!$C$15:$E$15,3)*INDEX(Assumptions!$C$16:$E$16,3))/100000 -> 47.952321 | J34: =(J19*INDEX(Assumptions!$C$21:$E$21,3)+J23*INDEX(Assumptions!$C$23:$E$23,3))/(1+INDEX(Assumptions!$C$15:$E$15,3)*INDEX(Assumptions!$C$16:$E$16,3))/100000 -> 61.154647
A35: Online short courses | B35: =0 -> 0 | C35: =C22*INDEX(Assumptions!$C$213:$E$213,1)/(1+INDEX(Assumptions!$C$15:$E$15,1)*INDEX(Assumptions!$C$16:$E$16,1))/100000 -> 0 | D35: =D22*INDEX(Assumptions!$C$213:$E$213,1)/(1+INDEX(Assumptions!$C$15:$E$15,1)*INDEX(Assumptions!$C$16:$E$16,1))/100000 -> 1.2699153 | E35: =0 -> 0 | F35: =F22*INDEX(Assumptions!$C$213:$E$213,2)/(1+INDEX(Assumptions!$C$15:$E$15,2)*INDEX(Assumptions!$C$16:$E$16,2))/100000 -> 3.8110169 | G35: =G22*INDEX(Assumptions!$C$213:$E$213,2)/(1+INDEX(Assumptions!$C$15:$E$15,2)*INDEX(Assumptions!$C$16:$E$16,2))/100000 -> 11.433051 | H35: =0 -> 0 | I35: =I22*INDEX(Assumptions!$C$213:$E$213,3)/(1+INDEX(Assumptions!$C$15:$E$15,3)*INDEX(Assumptions!$C$16:$E$16,3))/100000 -> 13.552542 | J35: =J22*INDEX(Assumptions!$C$213:$E$213,3)/(1+INDEX(Assumptions!$C$15:$E$15,3)*INDEX(Assumptions!$C$16:$E$16,3))/100000 -> 33.881356
A36: Adjacents: kit margin, alumni booking desk, brand partnerships | B36: =Outlook_Conservative!O56/100000 -> 0.029241971 | C36: =(C17*C7*INDEX(Assumptions!$C$243:$E$243,1)+INDEX(Assumptions!$C$217:$E$217,1)*INDEX(Assumptions!$C$219:$E$219,1)/(1+INDEX(Assumptions!$C$15:$E$15,1)*INDEX(Assumptions!$C$16:$E$16,1))+INDEX(Assumptions!$C$220:$E$220,1))/100000 -> 1.2440865 | D36: =(D17*D7*INDEX(Assumptions!$C$243:$E$243,1)+INDEX(Assumptions!$C$218:$E$218,1)*INDEX(Assumptions!$C$219:$E$219,1)/(1+INDEX(Assumptions!$C$15:$E$15,1)*INDEX(Assumptions!$C$16:$E$16,1))+INDEX(Assumptions!$C$221:$E$221,1))/100000 -> 2.0041722 | E36: =Outlook_Base!O56/100000 -> 0.37506667 | F36: =(F17*F7*INDEX(Assumptions!$C$243:$E$243,2)+INDEX(Assumptions!$C$217:$E$217,2)*INDEX(Assumptions!$C$219:$E$219,2)/(1+INDEX(Assumptions!$C$15:$E$15,2)*INDEX(Assumptions!$C$16:$E$16,2))+INDEX(Assumptions!$C$220:$E$220,2))/100000 -> 3.2954728 | G36: =(G17*G7*INDEX(Assumptions!$C$243:$E$243,2)+INDEX(Assumptions!$C$218:$E$218,2)*INDEX(Assumptions!$C$219:$E$219,2)/(1+INDEX(Assumptions!$C$15:$E$15,2)*INDEX(Assumptions!$C$16:$E$16,2))+INDEX(Assumptions!$C$221:$E$221,2))/100000 -> 6.5521387 | H36: =Outlook_Aggressive!O56/100000 -> 1.03259 | I36: =(I17*I7*INDEX(Assumptions!$C$243:$E$243,3)+INDEX(Assumptions!$C$217:$E$217,3)*INDEX(Assumptions!$C$219:$E$219,3)/(1+INDEX(Assumptions!$C$15:$E$15,3)*INDEX(Assumptions!$C$16:$E$16,3))+INDEX(Assumptions!$C$220:$E$220,3))/100000 -> 5.5924295 | J36: =(J17*J7*INDEX(Assumptions!$C$243:$E$243,3)+INDEX(Assumptions!$C$218:$E$218,3)*INDEX(Assumptions!$C$219:$E$219,3)/(1+INDEX(Assumptions!$C$15:$E$15,3)*INDEX(Assumptions!$C$16:$E$16,3))+INDEX(Assumptions!$C$221:$E$221,3))/100000 -> 10.13454
A37: Partner-hosted satellite (PNA share after host revenue share) | B37: =0 -> 0 | C37: =0 -> 0 | D37: =D24*D27/(1+INDEX(Assumptions!$C$15:$E$15,1)*INDEX(Assumptions!$C$16:$E$16,1))*(1-INDEX(Assumptions!$C$223:$E$223,1))/100000 -> 0 | E37: =0 -> 0 | F37: =0 -> 0 | G37: =G24*G27/(1+INDEX(Assumptions!$C$15:$E$15,2)*INDEX(Assumptions!$C$16:$E$16,2))*(1-INDEX(Assumptions!$C$223:$E$223,2))/100000 -> 0 | H37: =0 -> 0 | I37: =0 -> 0 | J37: =J24*J27/(1+INDEX(Assumptions!$C$15:$E$15,3)*INDEX(Assumptions!$C$16:$E$16,3))*(1-INDEX(Assumptions!$C$223:$E$223,3))/100000 -> 21.966102
A38: Total revenue | B38: =SUM(B30:B37) -> 16.714396 | C38: =SUM(C30:C37) -> 26.631759 | D38: =SUM(D30:D37) -> 36.657299 | E38: =SUM(E30:E37) -> 71.143533 | F38: =SUM(F30:F37) -> 120.01493 | G38: =SUM(G30:G37) -> 166.93116 | H38: =SUM(H30:H37) -> 134.55428 | I38: =SUM(I30:I37) -> 235.65821 | J38: =SUM(J30:J37) -> 334.642
A39: Revenue growth | B39: =0 -> 0 | C39: =C38/B38-1 -> 0.59334256 | D39: =D38/C38-1 -> 0.37645052 | E39: =0 -> 0 | F39: =F38/E38-1 -> 0.6869408 | G39: =G38/F38-1 -> 0.39092001 | H39: =0 -> 0 | I39: =I38/H38-1 -> 0.75139881 | J39: =J38/I38-1 -> 0.42003115
A40: Costs (₹ lakh)
