Workbook

Sheet README
A1: PNA market sizing model - TAM / SAM / SOM with tricity-India reconciliation
A2: Prepared by the Economics & Market Sizing agent, 2026-10-16. Build script: economics/build_scripts/build_market_sizing.py
A4: Purpose | B4: Size India's paid makeup-led training market (TAM), the North India slice a Chandigarh-led offline/hybrid academy can serve (SAM) and PNA's realistic Year-3 revenue (SOM); reconcile CA-05 (tricity) with CA-06 (India).
A5: Unit | B5: ₹ crore per year, nominal, current run-rate (≈FY2026-27). Market figures at quoted fees (GST-inclusive where quoted). PNA forecast revenue is ex-GST and is grossed up by 18% (A-ECO-23) for SOM shares.
A6: Sheets | B6: Assumptions (all inputs, IDs, sources, tags, Low/Base/High + selector) -> TAM_India -> Tricity_Recon -> SAM_North -> SOM_PNA -> Sizing_Tree (summary) ; Context_NotTAM ; Checks
A7: Colour code | B7: Blue = input; black = formula; yellow = key output. No hard-coded results in calculation sheets.
A8: Selector | B8: Assumptions!C3 picks Low/Base/High for the 'Selected' column and the Sizing_Tree 'Selected case' column. Calculation sheets show all three cases side by side.
A9: Reconciliation | B9: See Tricity_Recon §5-7: CA-06 retained; CA-05 restated to makeup-led scope; adopted tricity = mean of three methods ≈ ₹3.3 crore base.
A10: Guardrail | B10: The beauty products / salon services / wedding markets are listed only in Context_NotTAM and are never the education TAM.
A11: Limitations | B11: No primary enrolment data; makeup-led share (A-IND-04), fee mix (A-IND-05), participation (A-CHD-03) and reach shares (A-ECO-15/16) are hypotheses. Validate via mystery shopping, competitor intake checks and PNA enquiry-origin data.

Sheet Assumptions
A1: Assumptions register (inputs)
A2: Blue = input. Every model sheet references these cells. Tags: [FACT] sourced; [CLAIM] first-party/unverified; [EST] our estimate with arithmetic; [HYP] hypothesis to validate; [FOUNDER] founder-stated.
A3: Scenario selector | C3: Base | D3: <- choose Low / Base / High (drives column I 'Selected' and any sheet that uses it)
A4: Scenario index | C4: =MATCH($C$3,$K$4:$M$4,0) -> 2 | K4: Low | L4: Base | M4: High
A6: ID | B6: Description | C6: Low | D6: Base | E6: High | F6: Unit | G6: Source / rationale | H6: Tag | I6: Selected
A8: 1. India TAM inputs (from research/india_market_analysis.md §8-9; values unchanged)
A9: A-IND-01 | B9: B&WSSC-certified candidates per year (all beauty & wellness) | C9: 130000 | D9: 170000 | E9: 210000 | F9: learners/yr | G9: 10.25 lakh/8 yrs=1.28; 13 lakh/9=1.44; 20.7 lakh/10-11=1.88-2.07 (S-IND-02,-04,-05) | H9: [EST] | I9: =INDEX(C9:E9,$C$4) -> 170000
A10: A-IND-02 | B10: Organised share of vocational training (total = certified / share) | C10: 0.4 | D10: 0.4 | E10: 0.4 | F10: % | G10: KPMG: unorganised ≈60% of vocational education (S-IND-01 p.67) | H10: [EST] | I10: =INDEX(C10:E10,$C$4) -> 0.4
A11: A-IND-03 | B11: Paid (self-funded) share of trainees | C11: 0.64 | D11: 0.72 | E11: 0.8 | F11: % | G11: 60% unorganised (self-paid) + 40% organised x 10/30/50% fee-paying (S-IND-01, S-IND-04) | H11: [EST] | I11: =INDEX(C11:E11,$C$4) -> 0.72
A12: A-IND-04 | B12: Makeup-led share of paid learners | C12: 0.15 | D12: 0.25 | E12: 0.35 | F12: % | G12: Most uncertain input; 2 of top-5 aspired roles are makeup (S-IND-01 p.53); Meribindiya catalogue ~half makeup (S-IND-37) | H12: [HYP] | I12: =INDEX(C12:E12,$C$4) -> 0.25
A13: A-IND-05a | B13: Tier T1 entry/short share of makeup-led learners | C13: 0.55 | D13: 0.4 | E13: 0.25 | F13: % | G13: india_market_analysis §8.1a | H13: [HYP] | I13: =INDEX(C13:E13,$C$4) -> 0.4
A14: A-IND-05b | B14: Tier T1 representative fee | C14: 15000 | D14: 20000 | E14: 25000 | F14: ₹ | G14: Online micro 150-6,000; offline basics 10-35k (S-IND-27,-35,-54) | H14: [EST] | I14: =INDEX(C14:E14,$C$4) -> 20000
A15: A-IND-05c | B15: Tier T2 core professional share | C15: 0.3 | D15: 0.35 | E15: 0.35 | F15: % | G15: §8.1a | H15: [HYP] | I15: =INDEX(C15:E15,$C$4) -> 0.35
A16: A-IND-05d | B16: Tier T2 representative fee | C16: 45000 | D16: 55000 | E16: 65000 | F16: ₹ | G16: YMCA 54,355; Orane online 45,000; VLCC 78,000 (S-IND-25,-28,-33) | H16: [EST] | I16: =INDEX(C16:E16,$C$4) -> 55000
A17: A-IND-05e | B17: Tier T3 advanced/bridal share | C17: 0.13 | D17: 0.2 | E17: 0.3 | F17: % | G17: §8.1a | H17: [HYP] | I17: =INDEX(C17:E17,$C$4) -> 0.2
A18: A-IND-05f | B18: Tier T3 representative fee | C18: 100000 | D18: 130000 | E18: 150000 | F18: ₹ | G18: VLCC 1.66 lakh; Lakmé 1.2-1.8 lakh (S-IND-32,-34) | H18: [EST] | I18: =INDEX(C18:E18,$C$4) -> 130000
A19: A-IND-05g | B19: Tier T4 premium share | C19: 0.02 | D19: 0.05 | E19: 0.1 | F19: % | G19: §8.1a | H19: [HYP] | I19: =INDEX(C19:E19,$C$4) -> 0.05
A20: A-IND-05h | B20: Tier T4 representative fee | C20: 250000 | D20: 300000 | E20: 350000 | F20: ₹ | G20: Pearl 4.45 lakh incl GST; DBA 2.25-5.95 lakh (S-IND-23, S-NC-26) | H20: [EST] | I20: =INDEX(C20:E20,$C$4) -> 300000
... A30: X-BS-SECTOR | B30: Context only: Beauty & Salon sector size 2025P (NOT the education market) | C30: 76141 | D30: 76141 | E30: 76141 | F30: ₹ crore | G30: S-IND-01 Table 1 p.15 | H30: [FACT] | I30: =INDEX(C30:E30,$C$4) -> 76141
A31: 2. Demography and intensity (research/chandigarh_market_analysis.md; KPMG state tables)
A32: A-CHD-02 | B32: Women aged 17-35, tricity district catchment (Chandigarh UT + SAS Nagar + Panchkula), 2026 | C32: 420 | D32: 471 | E32: 520 | F32: 000 | G32: Cohort rebuild from Technical Group projections (S-CHD-01, -03, -04); A-CHD-01/02 | H32: [EST] | I32: =INDEX(C32:E32,$C$4) -> 471
A33: X-W-IND | B33: Women aged 17-35, India, 2026 | C33: 222944 | D33: 222944 | E33: 222944 | F33: 000 | G33: S-CHD-01 Table 20 cohort rebuild (A-CHD-08) | H33: [EST] | I33: =INDEX(C33:E33,$C$4) -> 222944
A34: X-W-ROR | B34: Women 17-35, rest of Punjab+Haryana+HP+J&K (excl. tricity) | C34: 12376 | D34: 12376 | E34: 12376 | F34: 000 | G34: chandigarh_market_analysis §8.3 (12,662 - 286 in tricity) | H34: [EST] | I34: =INDEX(C34:E34,$C$4) -> 12376
A35: X-W-CHD | B35: Women 17-35: Chandigarh UT | C35: 185 | D35: 185 | E35: 185 | F35: 000 | G35: §2 table | H35: [EST] | I35: =INDEX(C35:E35,$C$4) -> 185
A36: X-W-MOH | B36: Women 17-35: SAS Nagar (Mohali) district | C36: 183 | D36: 183 | E36: 183 | F36: 000 | G36: §2 table | H36: [EST] | I36: =INDEX(C36:E36,$C$4) -> 183
A37: X-W-PKL | B37: Women 17-35: Panchkula district | C37: 103 | D37: 103 | E37: 103 | F37: 000 | G37: §2 table | H37: [EST] | I37: =INDEX(C37:E37,$C$4) -> 103
A38: X-W-PB | B38: Women 17-35: Punjab excl. Mohali | C38: 4275 | D38: 4275 | E38: 4275 | F38: 000 | G38: 4,458 - 183 | H38: [EST] | I38: =INDEX(C38:E38,$C$4) -> 4275
A39: X-W-HR | B39: Women 17-35: Haryana excl. Panchkula | C39: 4627 | D39: 4627 | E39: 4627 | F39: 000 | G39: 4,730 - 103 | H39: [EST] | I39: =INDEX(C39:E39,$C$4) -> 4627
A40: X-W-HP | B40: Women 17-35: Himachal Pradesh | C40: 1097 | D40: 1097 | E40: 1097 | F40: 000 | G40: §2 table | H40: [EST] | I40: =INDEX(C40:E40,$C$4) -> 1097
A41: X-W-JK | B41: Women 17-35: J&K | C41: 2377 | D41: 2377 | E41: 2377 | F41: 000 | G41: §2 table | H41: [EST] | I41: =INDEX(C41:E41,$C$4) -> 2377
A42: X-BW-IND | B42: B&W share of state workforce: India | C42: 0.0241 | D42: 0.0241 | E42: 0.0241 | F42: % | G42: S-IND-01 pp.34-35 | H42: [FACT] | I42: =INDEX(C42:E42,$C$4) -> 0.0241
A43: X-BW-CHD | B43: B&W share of state workforce: Chandigarh | C43: 0.0616 | D43: 0.0616 | E43: 0.0616 | F43: % | G43: S-IND-01 (highest in India) | H43: [FACT] | I43: =INDEX(C43:E43,$C$4) -> 0.0616
... A48: A-CHD-06 | B48: Tricity affluence weight (income-based; cross-check for intensity) | C48: 1.68 | D48: 1.85 | E48: 2 | F48: x India | G48: RBI PCNSDP: Chandigarh 2.28x, Haryana 1.69x, Mohali 1.5x assumed (S-CHD-06) | H48: [EST] | I48: =INDEX(C48:E48,$C$4) -> 1.85
A49: A-ECO-01 | B49: Tricity demand-intensity index used in top-down share (Low = income weight low; Base = KPMG B&W workforce index; High = Chandigarh income multiple) | C49: 1.68 | D49: =Tricity_Recon!D12 -> 1.9029345 | E49: 2.28 | F49: x India | G49: Base computed on Tricity_Recon from KPMG state B&W shares weighted by women 17-35 | H49: [EST] | I49: =INDEX(C49:E49,$C$4) -> 1.9029345
A50: A-ECO-02 | B50: Urban/rural ratio of paid makeup-academy participation (k) | C50: 3 | D50: 5 | E50: 8 | F50: x | G50: Makeup academies are urban (S-LC §3 all in cities); rural trainees mostly scheme-funded (S-IND-01 p.52, §7.1) | H50: [HYP] | I50: =INDEX(C50:E50,$C$4) -> 5
A51: A-ECO-03 | B51: Urban share of tricity catchment population | C51: 0.68 | D51: 0.72 | E51: 0.76 | F51: % | G51: Chandigarh ~97% urban (Census 2011, S-CHD-02); Panchkula 55.8% (S-CHD-04); Mohali ~55% assumed; women-weighted | H51: [EST] | I51: =INDEX(C51:E51,$C$4) -> 0.72
A52: A-ECO-04 | B52: Urban share of India population 2026 | C52: 0.37 | D52: 0.36 | E52: 0.35 | F52: % | G52: Census 2011 31.1% + trend (general knowledge, not re-sourced) | H52: [EST] | I52: =INDEX(C52:E52,$C$4) -> 0.36
A53: A-CHD-04 | B53: Outstation (non-tricity) share of tricity students | C53: 0.15 | D53: 0.25 | E53: 0.3 | F53: % | G53: No student-origin data; A-CUS-28 15-35% of enquiries | H53: [HYP] | I53: =INDEX(C53:E53,$C$4) -> 0.25
A54: A-ECO-05 | B54: Rest-of-region demand-intensity index (PB/HR/HP/J&K) | C54: 1.1 | D54: =SAM_North!D9 -> 1.2946424 | E54: 1.45 | F54: x India | G54: Base computed from KPMG B&W shares weighted by women; urbanisation ≈ India so no urban factor | H54: [EST] | I54: =INDEX(C54:E54,$C$4) -> 1.2946424
A55: A-CHD-03 | B55: Annual participation of tricity resident women 17-35 in paid makeup/beauty-artistry course | C55: 0.0012 | D55: 0.002 | E55: 0.003 | F55: % | G55: Calibrated to bridal-MUA listing pipeline (A-CHD-07); unverified | H55: [HYP] | I55: =INDEX(C55:E55,$C$4) -> 0.002
...

Sheet TAM_India
A1: TAM: India paid makeup-led training tuition (₹ crore / yr, current run-rate)
A2: Re-computes india_market_analysis §8 with live formulas. Definition: learner-paid tuition for makeup-led professional/enthusiast training; excludes govt-funded places, kits, products, salon services.
A4: Step | B4: Formula | C4: Low | D4: Base | E4: High | F4: Assumption / note
A5: Method 1 - pipeline (council throughput -> paid -> makeup-led)
A6: a. Council-certified per year | B6: input | C6: =Assumptions!$C$9 -> 130000 | D6: =Assumptions!$D$9 -> 170000 | E6: =Assumptions!$E$9 -> 210000 | F6: A-IND-01
A7: b. Total vocational trainees per year | C7: =C6/Assumptions!$C$10 -> 325000 | D7: =D6/Assumptions!$D$10 -> 425000 | E7: =E6/Assumptions!$E$10 -> 525000 | F7: a / A-IND-02
A8: check: share of KPMG need | C8: =C7/Assumptions!$C$29 -> 0.4782056 | D8: =D7/Assumptions!$D$29 -> 0.62534578 | E8: =E7/Assumptions!$E$29 -> 0.77248596 | F8: b / 679,624
A9: c. Paid share | C9: =Assumptions!$C$11 -> 0.64 | D9: =Assumptions!$D$11 -> 0.72 | E9: =Assumptions!$E$11 -> 0.8 | F9: A-IND-03
A10: d. Paid learners, all beauty | C10: =C7*C9 -> 208000 | D10: =D7*D9 -> 306000 | E10: =E7*E9 -> 420000 | F10: b x c
A11: e. Makeup-led share | C11: =Assumptions!$C$12 -> 0.15 | D11: =Assumptions!$D$12 -> 0.25 | E11: =Assumptions!$E$12 -> 0.35 | F11: A-IND-04
A12: f. Makeup-led paid learners | C12: =C10*C11 -> 31200 | D12: =D10*D11 -> 76500 | E12: =E10*E11 -> 147000 | F12: d x e
A13: g. Blended fee per makeup-led learner (₹) | C13: =Assumptions!$C$13*Assumptions!$C$14+Assumptions!$C$15*Assumptions!$C$16+Assumptions!$C$17*Assumptions!$C$18+Assumptions!$C$19*Assumptions!$C$20 -> 39750 | D13: =Assumptions!$D$13*Assumptions!$D$14+Assumptions!$D$15*Assumptions!$D$16+Assumptions!$D$17*Assumptions!$D$18+Assumptions!$D$19*Assumptions!$D$20 -> 68250 | E13: =Assumptions!$E$13*Assumptions!$E$14+Assumptions!$E$15*Assumptions!$E$16+Assumptions!$E$17*Assumptions!$E$18+Assumptions!$E$19*Assumptions!$E$20 -> 109000 | F13: Σ tier share x tier fee (A-IND-05a..h)
A14: h. Makeup-led tuition revenue (₹ crore) | C14: =C12*C13/10000000 -> 124.02 | D14: =D12*D13/10000000 -> 522.1125 | E14: =E12*E13/10000000 -> 1602.3 | F14: f x g / 1e7
A15: i. Non-makeup learners | C15: =C10-C12 -> 176800 | D15: =D10-D12 -> 229500 | E15: =E10-E12 -> 273000 | F15: d - f
A16: k. Non-makeup revenue (₹ crore) | C16: =C15*Assumptions!$C$21/10000000 -> 176.8 | D16: =D15*Assumptions!$D$21/10000000 -> 298.35 | E16: =E15*Assumptions!$E$21/10000000 -> 491.4 | F16: i x A-IND-06
A17: l. All-beauty paid training (₹ crore) - context | C17: =C14+C16 -> 300.82 | D17: =D14+D16 -> 820.4625 | E17: =E14+E16 -> 2093.7 | F17: h + k
A19: Method 2 - supply side (chains x learners x independent multiple)
A20: a. Branded chain/franchise centres | C20: =Assumptions!$C$22 -> 300 | D20: =Assumptions!$D$22 -> 450 | E20: =Assumptions!$E$22 -> 600 | F20: A-IND-07
A21: b. Learners per centre per year | C21: =Assumptions!$C$23 -> 80 | D21: =Assumptions!$D$23 -> 110 | E21: =Assumptions!$E$23 -> 125 | F21: A-IND-08
A22: c. Organised private learners | C22: =C20*C21 -> 24000 | D22: =D20*D21 -> 49500 | E22: =E20*E21 -> 75000 | F22: a x b
A23: e. Total paid learners, all beauty | C23: =C22*(1+Assumptions!$C$24) -> 60000 | D23: =D22*(1+Assumptions!$D$24) -> 148500 | E23: =E22*(1+Assumptions!$E$24) -> 300000 | F23: c x (1 + A-IND-09)
A24: g. Makeup-led paid learners | C24: =C23*Assumptions!$C$12 -> 9000 | D24: =D23*Assumptions!$D$12 -> 37125 | E24: =E23*Assumptions!$E$12 -> 105000 | F24: e x A-IND-04 (shared with M1: not independent)
A25: i. Makeup-led tuition revenue (₹ crore) | C25: =C24*C13/10000000 -> 35.775 | D25: =D24*D13/10000000 -> 253.37813 | E25: =E24*E13/10000000 -> 1144.5 | F25: g x blended fee
A26: j. Non-makeup revenue (₹ crore) | C26: =(C23-C24)*Assumptions!$C$21/10000000 -> 51 | D26: =(D23-D24)*Assumptions!$D$21/10000000 -> 144.7875 | E26: =(E23-E24)*Assumptions!$E$21/10000000 -> 351
A27: k. All-beauty paid training (₹ crore) - context | C27: =C25+C26 -> 86.775 | D27: =D25+D26 -> 398.16562 | E27: =E25+E26 -> 1495.5
A29: Triangulated TAM (mean of methods) - CA-06
A30: TAM: makeup-led paid tuition, India (₹ crore/yr) | C30: =AVERAGE(C14,C25) -> 79.8975 | D30: =AVERAGE(D14,D25) -> 387.74531 | E30: =AVERAGE(E14,E25) -> 1373.4 | F30: equals CA-06 (₹80 / 390 / 1,370 crore)
A31: Makeup-led paid learners, India (mean of methods) | C31: =AVERAGE(C12,C24) -> 20100 | D31: =AVERAGE(D12,D24) -> 56812.5 | E31: =AVERAGE(E12,E24) -> 126000 | F31: used for share-of-India arithmetic
A32: Makeup-led learners per 1,000 women aged 17-35 | C32: =C31/Assumptions!$C$33 -> 0.09015717 | D32: =D31/Assumptions!$D$33 -> 0.25482857 | E32: =E31/Assumptions!$E$33 -> 0.56516435 | F32: national participation intensity
A33: Online / short-course layer (₹ crore) - reported separately | C33: =Assumptions!$C$25*Assumptions!$C$26/10000000 -> 3 | D33: =Assumptions!$D$25*Assumptions!$D$26/10000000 -> 22.5 | E33: =Assumptions!$E$25*Assumptions!$E$26/10000000 -> 120 | F33: A-IND-10a x 10b
A34: TAM incl. online layer (₹ crore) | C34: =C30+C33 -> 82.8975 | D34: =D30+D33 -> 410.24531 | E34: =E30+E33 -> 1493.4
A35: USD million equivalent (core TAM) | C35: =C30*10000000/Assumptions!$C$27/1000000 -> 9.0792614 | D35: =D30*10000000/Assumptions!$D$27/1000000 -> 44.061967 | E35: =E30*10000000/Assumptions!$E$27/1000000 -> 156.06818 | F35: display only
A36: Context: all-beauty paid training (mean, ₹ crore) - NOT the TAM | C36: =AVERAGE(C17,C27) -> 193.7975 | D36: =AVERAGE(D17,D27) -> 609.31406 | E36: =AVERAGE(E17,E27) -> 1794.6 | F36: wider beauty-education context
A37: Context: core TAM as % of Beauty & Salon sector 2025P | C37: =C30/Assumptions!$C$30 -> 0.0010493361 | D37: =D30/Assumptions!$D$30 -> 0.0050924641 | E37: =E30/Assumptions!$E$30 -> 0.018037588 | F37: shows education ≪ services market
A38: Context: 5-state regional slice by KPMG workforce share (₹ crore) | C38: =C30*Assumptions!$C$28 -> 6.1121587 | D38: =D30*Assumptions!$D$28 -> 29.662516 | E38: =E30*Assumptions!$E$28 -> 105.0651 | F38: A-IND-17 proxy; cross-check for SAM_North
A40: Methods share A-IND-04 and A-IND-05, so their agreement on order of magnitude is weaker evidence than it looks. Base is a planning number, not a market fact.

Sheet Tricity_Recon
A1: Reconciliation: tricity (CA-05) vs India (CA-06)
A2: Why ₹5.7 cr looked like 1.5% of a ₹390 cr India market when the tricity holds ~0.2% of India's young women - and the consistent set we adopt.
A4: Item | B4: Formula | C4: Low | D4: Base | E4: High | F4: Note
A5: 0. Demand-intensity indices (computed from [FACT] KPMG state B&W workforce shares)
A6: Chandigarh B&W intensity (state share / India share) | C6: =Assumptions!$C$43/Assumptions!$C$42 -> 2.5560166 | D6: =Assumptions!$D$43/Assumptions!$D$42 -> 2.5560166 | E6: =Assumptions!$E$43/Assumptions!$E$42 -> 2.5560166 | F6: 6.16% / 2.41%
A7: Punjab intensity (applied to Mohali) | C7: =Assumptions!$C$44/Assumptions!$C$42 -> 1.5103734 | D7: =Assumptions!$D$44/Assumptions!$D$42 -> 1.5103734 | E7: =Assumptions!$E$44/Assumptions!$E$42 -> 1.5103734
A8: Haryana intensity (applied to Panchkula) | C8: =Assumptions!$C$45/Assumptions!$C$42 -> 1.4273859 | D8: =Assumptions!$D$45/Assumptions!$D$42 -> 1.4273859 | E8: =Assumptions!$E$45/Assumptions!$E$42 -> 1.4273859
A9: Women weights: Chandigarh / Mohali / Panchkula (000) | C9: =Assumptions!$C$35+Assumptions!$C$36+Assumptions!$C$37 -> 471 | D9: =Assumptions!$D$35+Assumptions!$D$36+Assumptions!$D$37 -> 471 | E9: =Assumptions!$E$35+Assumptions!$E$36+Assumptions!$E$37 -> 471 | F9: sum = 471k
A10: Affluence weight (A-CHD-06) - cross-check | C10: =Assumptions!$C$48 -> 1.68 | D10: =Assumptions!$D$48 -> 1.85 | E10: =Assumptions!$E$48 -> 2 | F10: income-based; agrees with KPMG index within ~3% at base
A11: (spacer) | C11: =0 -> 0 | D11: =0 -> 0 | E11: =0 -> 0
A12: KPMG B&W intensity index, tricity (women-weighted) | C12: =(Assumptions!$C$35*C6+Assumptions!$C$36*C7+Assumptions!$C$37*C8)/C9 -> 1.9029345 | D12: =(Assumptions!$D$35*D6+Assumptions!$D$36*D7+Assumptions!$D$37*D8)/D9 -> 1.9029345 | E12: =(Assumptions!$E$35*E6+Assumptions!$E$36*E7+Assumptions!$E$37*E8)/E9 -> 1.9029345 | F12: Feeds A-ECO-01 base (1.90)
A14: 1. As published (scopes differ)
A15: CA-05 tricity learners = women x participation / (1 - outstation) | C15: =Assumptions!$C$32*1000*Assumptions!$C$55/(1-Assumptions!$C$53) -> 592.94118 | D15: =Assumptions!$D$32*1000*Assumptions!$D$55/(1-Assumptions!$D$53) -> 1256 | E15: =Assumptions!$E$32*1000*Assumptions!$E$55/(1-Assumptions!$E$53) -> 2228.5714 | F15: chandigarh_market_analysis §8.1: 593 / 1,256 / 2,229. Scope: makeup + beauty-artistry; participation calibrated to bridal-MUA pipeline
A16: CA-05 tricity revenue (₹ crore) | C16: =C15*Assumptions!$C$56/10000000 -> 1.7788235 | D16: =D15*Assumptions!$D$56/10000000 -> 5.652 | E16: =E15*Assumptions!$E$56/10000000 -> 13.371429 | F16: 1.8 / 5.7 / 13.4
A17: CA-06 India TAM (₹ crore) | C17: =TAM_India!C30 -> 79.8975 | D17: =TAM_India!D30 -> 387.74531 | E17: =TAM_India!E30 -> 1373.4 | F17: 80 / 390 / 1,370
A18: Apparent tricity share of India (CA-05 / CA-06) | C18: =C16/C17 -> 0.02226382 | D18: =D16/D17 -> 0.014576579 | E18: =E16/E17 -> 0.0097360045 | F18: the 'open reconciliation': ~1.5% at base
A19: Tricity share of India women 17-35 | C19: =Assumptions!$C$32/Assumptions!$C$33 -> 0.0018838812 | D19: =Assumptions!$D$32/Assumptions!$D$33 -> 0.0021126382 | E19: =Assumptions!$E$32/Assumptions!$E$33 -> 0.0023324243 | F19: ~0.21%
A21: 2. Method A - top-down from India TAM (national participation x tricity intensity)
A22: India makeup-led paid learners | C22: =TAM_India!C31 -> 20100 | D22: =TAM_India!D31 -> 56812.5 | E22: =TAM_India!E31 -> 126000 | F22: TAM_India mean of methods
A23: x tricity population share | C23: =C19 -> 0.0018838812 | D23: =D19 -> 0.0021126382 | E23: =E19 -> 0.0023324243
A24: x demand-intensity index (A-ECO-01) | C24: =Assumptions!$C$49 -> 1.68 | D24: =Assumptions!$D$49 -> 1.9029345 | E24: =Assumptions!$E$49 -> 2.28 | F24: B&W workforce / affluence
A25: x urban-concentration factor = (uT*k + 1-uT)/(uI*k + 1-uI) | C25: =(Assumptions!$C$51*Assumptions!$C$50+1-Assumptions!$C$51)/(Assumptions!$C$52*Assumptions!$C$50+1-Assumptions!$C$52) -> 1.3563218 | D25: =(Assumptions!$D$51*Assumptions!$D$50+1-Assumptions!$D$51)/(Assumptions!$D$52*Assumptions!$D$50+1-Assumptions!$D$52) -> 1.5901639 | E25: =(Assumptions!$E$51*Assumptions!$E$50+1-Assumptions!$E$51)/(Assumptions!$E$52*Assumptions!$E$50+1-Assumptions!$E$52) -> 1.8318841 | F25: A-ECO-02..04. May overlap partly with the intensity index (both rise with urbanisation) - flagged
A26: / (1 - outstation inflow) | C26: =1/(1-Assumptions!$C$53) -> 1.1764706 | D26: =1/(1-Assumptions!$D$53) -> 1.3333333 | E26: =1/(1-Assumptions!$E$53) -> 1.4285714 | F26: tricity counts students who come from home states
A27: Tricity share of India makeup-led learners (product) | C27: =C23*C24*C25*C26 -> 0.0050501771 | D27: =D23*D24*D25*D26 -> 0.0085237283 | E27: =E23*E24*E25*E26 -> 0.013916895
A28: Method A learners | C28: =C22*C27 -> 101.50856 | D28: =D22*D27 -> 484.25431 | E28: =E22*E27 -> 1753.5287
A29: Method A revenue at tricity fee (₹ crore) | C29: =C28*Assumptions!$C$56/10000000 -> 0.30452568 | D29: =D28*Assumptions!$D$56/10000000 -> 2.1791444 | E29: =E28*Assumptions!$E$56/10000000 -> 10.521172 | F29: tricity fee (A-CHD-05) < India blended fee (no T4 premium tier locally)
A31: 3. Method B - CA-05 bottom-up restated to the TAM scope (makeup-led only)
A32: CA-05 learners (makeup + beauty-artistry) | C32: =C15 -> 592.94118 | D32: =D15 -> 1256 | E32: =E15 -> 2228.5714
A33: x makeup-led share (A-ECO-06) | C33: =Assumptions!$C$58 -> 0.6 | D33: =Assumptions!$D$58 -> 0.7 | E33: =Assumptions!$E$58 -> 0.8 | F33: scope harmonisation
A34: Method B learners (makeup-led) | C34: =C32*C33 -> 355.76471 | D34: =D32*D33 -> 879.2 | E34: =E32*E33 -> 1782.8571
A35: Method B revenue (₹ crore) | C35: =C34*Assumptions!$C$56/10000000 -> 1.0672941 | D35: =D34*Assumptions!$D$56/10000000 -> 3.9564 | E35: =E34*Assumptions!$E$56/10000000 -> 10.697143
A37: 4. Method C - supply-side count of tricity providers (cross-check)
A38: Chain/brand centres x makeup learners | C38: =Assumptions!$C$59*Assumptions!$C$60 -> 210 | D38: =Assumptions!$D$59*Assumptions!$D$60 -> 315 | E38: =Assumptions!$E$59*Assumptions!$E$60 -> 420 | F38: A-ECO-07 x 08
A39: Independent institutes x learners | C39: =Assumptions!$C$61*Assumptions!$C$62 -> 125 | D39: =Assumptions!$D$61*Assumptions!$D$62 -> 200 | E39: =Assumptions!$E$61*Assumptions!$E$62 -> 300 | F39: A-ECO-09 x 10
A40: Founder-led academies x learners | C40: =Assumptions!$C$63*Assumptions!$C$64 -> 120 | D40: =Assumptions!$D$63*Assumptions!$D$64 -> 200 | E40: =Assumptions!$E$63*Assumptions!$E$64 -> 320 | F40: A-ECO-11 x 12
A41: Tutors (UrbanPro listings x active learners per listing) | C41: =Assumptions!$C$65*Assumptions!$C$66 -> 66.6 | D41: =Assumptions!$D$65*Assumptions!$D$66 -> 99.9 | E41: =Assumptions!$E$65*Assumptions!$E$66 -> 133.2 | F41: A-ECO-13 x 14
A42: Method C learners | C42: =SUM(C38:C41) -> 521.6 | D42: =SUM(D38:D41) -> 814.9 | E42: =SUM(E38:E41) -> 1173.2
A43: Method C revenue (₹ crore) | C43: =C42*Assumptions!$C$56/10000000 -> 1.5648 | D43: =D42*Assumptions!$D$56/10000000 -> 3.66705 | E43: =E42*Assumptions!$E$56/10000000 -> 7.0392
A45: 5. ADOPTED CONSISTENT SET - tricity makeup-led paid training (planning band = spread of the three methods' base cases)
A46: Reconciled tricity learners (Low = min, Base = mean, High = max of method base cases) | C46: =MIN($D$28,$D$34,$D$42) -> 484.25431 | D46: =AVERAGE($D$28,$D$34,$D$42) -> 726.1181 | E46: =MAX($D$28,$D$34,$D$42) -> 879.2 | F46: Method disagreement is the dominant uncertainty; each method's own low/high compounds extreme inputs (shown below)
...

Sheet SAM_North
A1: SAM: North India market serviceable by a Chandigarh-led offline/hybrid academy (₹ crore / yr, quoted fees)
A2: Five components built on the same participation chain as the reconciled tricity number; outstation learners already inside the tricity figure are netted out of the regional component.
A4: Item | B4: Formula | C4: Low | D4: Base | E4: High | F4: Note
A5: Rest-of-region intensity (PB/HR/HP/J&K excl. tricity)
A6: Σ women x state B&W intensity | C6: =(Assumptions!$C$38*Assumptions!$C$44+Assumptions!$C$39*Assumptions!$C$45+Assumptions!$C$40*Assumptions!$C$46+Assumptions!$C$41*Assumptions!$C$47)/Assumptions!$C$42 -> 16022.494 | D6: =(Assumptions!$D$38*Assumptions!$D$44+Assumptions!$D$39*Assumptions!$D$45+Assumptions!$D$40*Assumptions!$D$46+Assumptions!$D$41*Assumptions!$D$47)/Assumptions!$D$42 -> 16022.494 | E6: =(Assumptions!$E$38*Assumptions!$E$44+Assumptions!$E$39*Assumptions!$E$45+Assumptions!$E$40*Assumptions!$E$46+Assumptions!$E$41*Assumptions!$E$47)/Assumptions!$E$42 -> 16022.494
A7: Σ women (000) | C7: =Assumptions!$C$38+Assumptions!$C$39+Assumptions!$C$40+Assumptions!$C$41 -> 12376 | D7: =Assumptions!$D$38+Assumptions!$D$39+Assumptions!$D$40+Assumptions!$D$41 -> 12376 | E7: =Assumptions!$E$38+Assumptions!$E$39+Assumptions!$E$40+Assumptions!$E$41 -> 12376 | F7: equals X-W-ROR 12,376
A8: (spacer) | C8: =0 -> 0 | D8: =0 -> 0 | E8: =0 -> 0
A9: KPMG intensity index, rest of region | C9: =C6/C7 -> 1.2946424 | D9: =D6/D7 -> 1.2946424 | E9: =E6/E7 -> 1.2946424 | F9: Feeds A-ECO-05 base (1.30)
A11: SAM-1 Tricity (reconciled, Tricity_Recon §5)
A12: Tricity makeup-led learners | C12: =Tricity_Recon!C46 -> 484.25431 | D12: =Tricity_Recon!D46 -> 726.1181 | E12: =Tricity_Recon!E46 -> 879.2
A13: SAM-1 revenue (₹ crore) | C13: =Tricity_Recon!C47 -> 1.4527629 | D13: =Tricity_Recon!D47 -> 3.2675315 | E13: =Tricity_Recon!E47 -> 5.2752
A15: SAM-2 Regional destination learners (offline, travel to Chandigarh)
A16: Rest-of-region makeup-led learners | C16: =TAM_India!C31*Assumptions!$C$34/Assumptions!$C$33*Assumptions!$C$54 -> 1227.3636 | D16: =TAM_India!D31*Assumptions!$D$34/Assumptions!$D$33*Assumptions!$D$54 -> 4082.9891 | E16: =TAM_India!E31*Assumptions!$E$34/Assumptions!$E$33*Assumptions!$E$54 -> 10141.987 | F16: India learners x population share x A-ECO-05
A17: x reachable share (A-ECO-15) | C17: =Assumptions!$C$68 -> 0.1 | D17: =Assumptions!$D$68 -> 0.15 | E17: =Assumptions!$E$68 -> 0.2
A18: Reachable regional learners | C18: =C16*C17 -> 122.73636 | D18: =D16*D17 -> 612.44837 | E18: =E16*E17 -> 2028.3974
A19: less: already counted as tricity outstation inflow | C19: =Tricity_Recon!C48 -> 72.638147 | D19: =Tricity_Recon!D48 -> 181.52953 | E19: =Tricity_Recon!E48 -> 263.76 | F19: avoid double count
A20: Net incremental regional learners | C20: =MAX(0,C18-C19) -> 50.098217 | D20: =MAX(0,D18-D19) -> 430.91884 | E20: =MAX(0,E18-E19) -> 1764.6374
A21: SAM-2 revenue (₹ crore) | C21: =C20*Assumptions!$C$56/10000000 -> 0.15029465 | D21: =D20*Assumptions!$D$56/10000000 -> 1.9391348 | E21: =E20*Assumptions!$E$56/10000000 -> 10.587825 | F21: at tricity fee
A23: SAM-3 Hybrid (online theory + short Chandigarh practical) for learners beyond offline reach
A24: Non-reachable regional learners | C24: =C16-C18 -> 1104.6273 | D24: =D16-D18 -> 3470.5408 | E24: =E16-E18 -> 8113.5898
A25: x hybrid-willing share (A-ECO-16) | C25: =Assumptions!$C$69 -> 0.05 | D25: =Assumptions!$D$69 -> 0.08 | E25: =Assumptions!$E$69 -> 0.12
A26: Hybrid learners | C26: =C24*C25 -> 55.231364 | D26: =D24*D25 -> 277.64326 | E26: =E24*E25 -> 973.63077
A27: SAM-3 revenue (₹ crore) | C27: =C26*Assumptions!$C$70/10000000 -> 0.22092546 | D27: =D26*Assumptions!$D$70/10000000 -> 1.3882163 | E27: =E26*Assumptions!$E$70/10000000 -> 5.8417846 | F27: A-ECO-17 fee
A29: SAM-4 Working-artist CPD / masterclasses (tricity + reachable region) - scope extension, see note
A30: Working makeup artists in reach | C30: =Assumptions!$C$71+Assumptions!$C$72 -> 2800 | D30: =Assumptions!$D$71+Assumptions!$D$72 -> 4000 | E30: =Assumptions!$E$71+Assumptions!$E$72 -> 5300 | F30: A-ECO-18 + 19
A31: Paying CPD participants per year | C31: =C30*Assumptions!$C$73 -> 560 | D31: =D30*Assumptions!$D$73 -> 1200 | E31: =E30*Assumptions!$E$73 -> 2120
A32: SAM-4 revenue (₹ crore) | C32: =C31*Assumptions!$C$74/10000000 -> 0.448 | D32: =D31*Assumptions!$D$74/10000000 -> 1.2 | E32: =E31*Assumptions!$E$74/10000000 -> 2.544 | F32: CPD by working pros is largely outside the TAM's entrant-based learner count; shown separately so it does not inflate TAM comparisons
A34: SAM-5 Online short-course layer reachable with Hindi/Punjabi founder content
A35: SAM-5 revenue (₹ crore) | C35: =TAM_India!C33*Assumptions!$C$75 -> 0.75 | D35: =TAM_India!D33*Assumptions!$D$75 -> 7.875 | E35: =TAM_India!E33*Assumptions!$E$75 -> 54 | F35: India online layer x A-ECO-22
A37: SAM totals
A38: SAM core: offline + hybrid + CPD (SAM-1..4), ₹ crore | C38: =C13+C21+C27+C32 -> 2.271983 | D38: =D13+D21+D27+D32 -> 7.7948826 | E38: =E13+E21+E27+E32 -> 24.248809 | F38: headline SAM
A39: SAM online layer (SAM-5), ₹ crore | C39: =C35 -> 0.75 | D39: =D35 -> 7.875 | E39: =E35 -> 54 | F39: low-ticket, crowded (Orane, Airblack, YouTube)
A40: SAM total, ₹ crore | C40: =C38+C39 -> 3.021983 | D40: =D38+D39 -> 15.669883 | E40: =E38+E39 -> 78.248809
A41: Training learners in SAM-1..3 (excl. CPD and online) | C41: =C12+C20+C26 -> 589.5839 | D41: =D12+D20+D26 -> 1434.6802 | E41: =E12+E20+E26 -> 3617.4682
A42: SAM total / TAM incl. online | C42: =C40/TAM_India!C34 -> 0.036454453 | D42: =D40/TAM_India!D34 -> 0.038196372 | E42: =E40/TAM_India!E34 -> 0.052396417
A43: Cross-check: 5-state makeup-led market bottom-up (tricity + all rest-of-region learners x tricity fee) | C43: =C13+C16*Assumptions!$C$56/10000000 -> 5.1348539 | D43: =D13+D16*Assumptions!$D$56/10000000 -> 21.640983 | E43: =E13+E16*Assumptions!$E$56/10000000 -> 66.127123 | F43: compare with next row
A44: Cross-check: TAM x 7.65% workforce proxy, restated at tricity/India fee ratio | C44: =TAM_India!C38*Assumptions!$C$56/TAM_India!C13 -> 4.61295 | D44: =TAM_India!D38*Assumptions!$D$56/TAM_India!D13 -> 19.557703 | E44: =TAM_India!E38*Assumptions!$E$56/TAM_India!E13 -> 57.834 | F44: two routes should be the same order of magnitude

Sheet SOM_PNA
A1: SOM: PNA's realistic Year-3 revenue and implied share of each SAM component
A2: SOM = Year-3 revenue from business_forecast.xlsx 3yr_Scenarios (Low=Conservative, Base, High=Aggressive), converted to quoted (GST-inclusive) prices to match market sizing.
A4: Item | B4: Formula | C4: Low (Cons.) | D4: Base | E4: High (Aggr.) | F4: Note
A5: SOM by component (₹ crore, quoted incl. GST) and implied share
A6: Tricity flagship (SAM-1): PNA Y3 revenue | C6: =Assumptions!$C$78*(1+Assumptions!$C$76)/100 -> 0.230218 | D6: =Assumptions!$D$78*(1+Assumptions!$D$76)/100 -> 0.83662 | E6: =Assumptions!$E$78*(1+Assumptions!$E$76)/100 -> 1.233926 | F6: SOM-TRI x (1+GST) / 100
A7: Tricity flagship (SAM-1): implied share of SAM component | C7: =IFERROR(C6/SAM_North!C13,0) -> 0.15846908 | D7: =IFERROR(D6/SAM_North!D13,0) -> 0.25604038 | E7: =IFERROR(E6/SAM_North!E13,0) -> 0.23391075
A8: Regional destination (SAM-2): PNA Y3 revenue | C8: =Assumptions!$C$79*(1+Assumptions!$C$76)/100 -> 0.04012 | D8: =Assumptions!$D$79*(1+Assumptions!$D$76)/100 -> 0.28851 | E8: =Assumptions!$E$79*(1+Assumptions!$E$76)/100 -> 0.891608 | F8: SOM-REG x (1+GST) / 100
A9: Regional destination (SAM-2): implied share of SAM component | C9: =IFERROR(C8/SAM_North!C21,0) -> 0.2669423 | D9: =IFERROR(D8/SAM_North!D21,0) -> 0.14878285 | E9: =IFERROR(E8/SAM_North!E21,0) -> 0.084210688
A10: Hybrid (SAM-3): PNA Y3 revenue | C10: =Assumptions!$C$80*(1+Assumptions!$C$76)/100 -> 0.054634 | D10: =Assumptions!$D$80*(1+Assumptions!$D$76)/100 -> 0.29677 | E10: =Assumptions!$E$80*(1+Assumptions!$E$76)/100 -> 0.58233 | F10: SOM-HYB x (1+GST) / 100
A11: Hybrid (SAM-3): implied share of SAM component | C11: =IFERROR(C10/SAM_North!C27,0) -> 0.24729608 | D11: =IFERROR(D10/SAM_North!D27,0) -> 0.21377792 | E11: =IFERROR(E10/SAM_North!E27,0) -> 0.099683579
A12: Working-artist CPD (SAM-4): PNA Y3 revenue | C12: =Assumptions!$C$81*(1+Assumptions!$C$76)/100 -> 0.068912 | D12: =Assumptions!$D$81*(1+Assumptions!$D$76)/100 -> 0.319072 | E12: =Assumptions!$E$81*(1+Assumptions!$E$76)/100 -> 0.72157 | F12: SOM-CPD x (1+GST) / 100
A13: Working-artist CPD (SAM-4): implied share of SAM component | C13: =IFERROR(C12/SAM_North!C32,0) -> 0.15382143 | D13: =IFERROR(D12/SAM_North!D32,0) -> 0.26589333 | E13: =IFERROR(E12/SAM_North!E32,0) -> 0.28363601
A14: Online (SAM-5): PNA Y3 revenue | C14: =Assumptions!$C$82*(1+Assumptions!$C$76)/100 -> 0.014986 | D14: =Assumptions!$D$82*(1+Assumptions!$D$76)/100 -> 0.134874 | E14: =Assumptions!$E$82*(1+Assumptions!$E$76)/100 -> 0.399784 | F14: SOM-ONL x (1+GST) / 100
A15: Online (SAM-5): implied share of SAM component | C15: =IFERROR(C14/SAM_North!C35,0) -> 0.019981333 | D15: =IFERROR(D14/SAM_North!D35,0) -> 0.017126857 | E15: =IFERROR(E14/SAM_North!E35,0) -> 0.0074034074
A16: Learner-share test (primary: PNA charges ~1.8x the tricity average fee, so revenue share overstates position)
A17: PNA Y3 tricity career learners / tricity makeup-led learners (SAM-1) | C17: =Assumptions!$C$84/SAM_North!C12 -> 0.06938503 | D17: =Assumptions!$D$84/SAM_North!D12 -> 0.12711431 | E17: =Assumptions!$E$84/SAM_North!E12 -> 0.11089627 | F17: Chandigarh agent: 10-30% is the plausible single-centre band
A18: PNA Y3 out-of-town career learners / net regional reachable learners (SAM-2) | C18: =IFERROR(Assumptions!$C$85/(SAM_North!C20+Tricity_Recon!C48),0) -> 0.06029183 | D18: =IFERROR(Assumptions!$D$85/(SAM_North!D20+Tricity_Recon!D48),0) -> 0.064658512 | E18: =IFERROR(Assumptions!$E$85/(SAM_North!E20+Tricity_Recon!E48),0) -> 0.046835003 | F18: denominator incl. inflow already in tricity
A19: PNA Y3 hybrid learners / hybrid-willing learners (SAM-3) | C19: =IFERROR(Assumptions!$C$86/SAM_North!C26,0) -> 0.14484524 | D19: =IFERROR(Assumptions!$D$86/SAM_North!D26,0) -> 0.12606105 | E19: =IFERROR(Assumptions!$E$86/SAM_North!E26,0) -> 0.055359795
A20: PNA Y3 tricity career learners / CA-05 tricity learners (BM test: flag if >10% without regional engine) | C20: =Assumptions!$C$84/Tricity_Recon!C15 -> 0.056666667 | D20: =Assumptions!$D$84/Tricity_Recon!D15 -> 0.073487261 | E20: =Assumptions!$E$84/Tricity_Recon!E15 -> 0.04375
A21: SOM training total (₹ crore, quoted) | C21: =C6+C8+C10+C12+C14 -> 0.40887 | D21: =D6+D8+D10+D12+D14 -> 1.875846 | E21: =E6+E8+E10+E12+E14 -> 3.829218
A22: SOM / SAM core (excl. online) | C22: =(C21-C14)/SAM_North!C38 -> 0.17336573 | D22: =(D21-D14)/SAM_North!D38 -> 0.22334807 | E22: =(E21-E14)/SAM_North!E38 -> 0.1414269
A23: SOM / SAM total | C23: =C21/SAM_North!C40 -> 0.13529857 | D23: =D21/SAM_North!D40 -> 0.11971028 | E23: =E21/SAM_North!E40 -> 0.048936438
A24: SOM / TAM incl. online | C24: =C21/TAM_India!C34 -> 0.0049322356 | D24: =D21/TAM_India!D34 -> 0.0045724983 | E24: =E21/TAM_India!E34 -> 0.002564094 | F24: benchmark: Mao Geping ≈1% of China makeup training (S-INT-01)
A25: Adjacent revenue outside training market (₹ crore, quoted) | C25: =Assumptions!$C$83*(1+Assumptions!$C$76)/100 -> 0.0236 | D25: =Assumptions!$D$83*(1+Assumptions!$D$76)/100 -> 0.077172 | E25: =Assumptions!$E$83*(1+Assumptions!$E$76)/100 -> 0.119534 | F25: kits, services desk, partnerships - not counted in SOM share
A27: Today (illustrative baseline - CA-01 x assumed fees, NOT actual revenue)
A28: PNA illustrative baseline (₹ crore, quoted) | C28: =Assumptions!$C$88*(1+Assumptions!$C$76)/100 -> 0.079178 | D28: =Assumptions!$D$88*(1+Assumptions!$D$76)/100 -> 0.195998 | E28: =Assumptions!$E$88*(1+Assumptions!$E$76)/100 -> 0.294056 | F28: CA-01 50 students x CA-02 fee mix
A29: Implied baseline share of tricity SAM-1 | C29: =C28/SAM_North!C13 -> 0.054501666 | D29: =D28/SAM_North!D13 -> 0.059983508 | E29: =E28/SAM_North!E13 -> 0.0557431 | F29: sanity: ~5-10% for an established founder-led studio-academy
A30: Y3 SOM multiple of today | C30: =IFERROR(C21/C28,0) -> 5.1639344 | D30: =IFERROR(D21/D28,0) -> 9.5707405 | E30: =IFERROR(E21/E28,0) -> 13.022071
A31: ILLUSTRATIVE: today's PNA share of tricity makeup-led learners (CA-01 / reconciled learners; Low = CA-01 low / market high, High = CA-01 high / market low) | C31: =Assumptions!$C$87/Tricity_Recon!$E$46 -> 0.034121929 | D31: =Assumptions!$D$87/Tricity_Recon!$D$46 -> 0.068859321 | E31: =Assumptions!$E$87/Tricity_Recon!$C$46 -> 0.12390184 | F31: All PNA students (career + short) over all makeup-led learners (incl. short-course). Not quoted as a fact until CA-01 is confirmed (V1)
A33: Share tests: a single centre at >25% of tricity, >30% of CPD or >5% of online would be a red flag (chandigarh_market_analysis §8.2; international_benchmarks §2).

Sheet Sizing_Tree
A1: Market-sizing tree (₹ crore / yr unless stated)
A2: Never present the beauty products/services market as the education market (see Context_NotTAM).
A4: Node | C4: Low | D4: Base | E4: High | F4: Selected case | G4: Definition / source
A5: TAM India: paid makeup-led training tuition | C5: =TAM_India!C30 -> 79.8975 | D5: =TAM_India!D30 -> 387.74531 | E5: =TAM_India!E30 -> 1373.4 | F5: =INDEX(C5:E5,Assumptions!$C$4) -> 387.74531 | G5: CA-06; TAM_India (mean of pipeline and supply methods)
A6: + India online / short-course layer | C6: =TAM_India!C33 -> 3 | D6: =TAM_India!D33 -> 22.5 | E6: =TAM_India!E33 -> 120 | F6: =INDEX(C6:E6,Assumptions!$C$4) -> 22.5 | G6: A-IND-10; reported separately
A7: (context) 5-state North slice by KPMG workforce share | C7: =TAM_India!C38 -> 6.1121587 | D7: =TAM_India!D38 -> 29.662516 | E7: =TAM_India!E38 -> 105.0651 | F7: =INDEX(C7:E7,Assumptions!$C$4) -> 29.662516 | G7: A-IND-17 x TAM; not used directly
A8: SAM North India serviceable by a Chandigarh-led academy (total) | C8: =SAM_North!C40 -> 3.021983 | D8: =SAM_North!D40 -> 15.669883 | E8: =SAM_North!E40 -> 78.248809 | F8: =INDEX(C8:E8,Assumptions!$C$4) -> 15.669883 | G8: SAM_North
A9: SAM core (offline + hybrid + CPD) | C9: =SAM_North!C38 -> 2.271983 | D9: =SAM_North!D38 -> 7.7948826 | E9: =SAM_North!E38 -> 24.248809 | F9: =INDEX(C9:E9,Assumptions!$C$4) -> 7.7948826 | G9: headline SAM
A10: SAM-1 Tricity makeup-led (reconciled) | C10: =SAM_North!C13 -> 1.4527629 | D10: =SAM_North!D13 -> 3.2675315 | E10: =SAM_North!E13 -> 5.2752 | F10: =INDEX(C10:E10,Assumptions!$C$4) -> 3.2675315 | G10: Tricity_Recon §5 (replaces CA-05 for planning)
A11: SAM-2 Regional destination (net of inflow) | C11: =SAM_North!C21 -> 0.15029465 | D11: =SAM_North!D21 -> 1.9391348 | E11: =SAM_North!E21 -> 10.587825 | F11: =INDEX(C11:E11,Assumptions!$C$4) -> 1.9391348 | G11: PB/HR/HP/J&K reachable offline
A12: SAM-3 Hybrid beyond offline reach | C12: =SAM_North!C27 -> 0.22092546 | D12: =SAM_North!D27 -> 1.3882163 | E12: =SAM_North!E27 -> 5.8417846 | F12: =INDEX(C12:E12,Assumptions!$C$4) -> 1.3882163
A13: SAM-4 Working-artist CPD / masterclasses | C13: =SAM_North!C32 -> 0.448 | D13: =SAM_North!D32 -> 1.2 | E13: =SAM_North!E32 -> 2.544 | F13: =INDEX(C13:E13,Assumptions!$C$4) -> 1.2 | G13: scope extension (repeat buyers)
A14: SAM-5 Online layer (North-reachable) | C14: =SAM_North!C35 -> 0.75 | D14: =SAM_North!D35 -> 7.875 | E14: =SAM_North!E35 -> 54 | F14: =INDEX(C14:E14,Assumptions!$C$4) -> 7.875
A15: SOM PNA Year-3 revenue (quoted, training only) | C15: =SOM_PNA!C21 -> 0.40887 | D15: =SOM_PNA!D21 -> 1.875846 | E15: =SOM_PNA!E21 -> 3.829218 | F15: =INDEX(C15:E15,Assumptions!$C$4) -> 1.875846 | G15: business_forecast 3yr_Scenarios (Cons/Base/Aggr)
A16: SOM as % of SAM core (excl. online) | C16: =SOM_PNA!C22 -> 0.17336573 | D16: =SOM_PNA!D22 -> 0.22334807 | E16: =SOM_PNA!E22 -> 0.1414269 | F16: =INDEX(C16:E16,Assumptions!$C$4) -> 0.22334807
A17: PNA learner share of tricity makeup-led learners (Y3) | C17: =SOM_PNA!C17 -> 0.06938503 | D17: =SOM_PNA!D17 -> 0.12711431 | E17: =SOM_PNA!E17 -> 0.11089627 | F17: =INDEX(C17:E17,Assumptions!$C$4) -> 0.12711431 | G17: primary share test
A18: SOM as % of TAM incl. online | C18: =SOM_PNA!C24 -> 0.0049322356 | D18: =SOM_PNA!D24 -> 0.0045724983 | E18: =SOM_PNA!E24 -> 0.002564094 | F18: =INDEX(C18:E18,Assumptions!$C$4) -> 0.0045724983
A19: Today PNA illustrative baseline (NOT actual revenue) | C19: =SOM_PNA!C28 -> 0.079178 | D19: =SOM_PNA!D28 -> 0.195998 | E19: =SOM_PNA!E28 -> 0.294056 | F19: =INDEX(C19:E19,Assumptions!$C$4) -> 0.195998 | G19: CA-01 x CA-02 assumptions
A20: Illustrative: today's PNA share of tricity makeup-led learners | C20: =SOM_PNA!C31 -> 0.034121929 | D20: =SOM_PNA!D31 -> 0.068859321 | E20: =SOM_PNA!E31 -> 0.12390184 | F20: =INDEX(C20:E20,Assumptions!$C$4) -> 0.068859321 | G20: CA-01 / reconciled learners; to confirm with V1
A21: Learners: India makeup-led paid learners | C21: =TAM_India!C31 -> 20100 | D21: =TAM_India!D31 -> 56812.5 | E21: =TAM_India!E31 -> 126000 | F21: =INDEX(C21:E21,Assumptions!$C$4) -> 56812.5
A22: Learners: tricity makeup-led (reconciled) | C22: =Tricity_Recon!C46 -> 484.25431 | D22: =Tricity_Recon!D46 -> 726.1181 | E22: =Tricity_Recon!E46 -> 879.2 | F22: =INDEX(C22:E22,Assumptions!$C$4) -> 726.1181
A24: Selected case follows the selector on Assumptions!C3 (Low / Base / High).

Sheet Context_NotTAM
A1: Context only - these are NOT the education market and must never be presented as TAM
A4: Market | B4: Figure | C4: Unit | D4: Source | E4: Why excluded
A5: Beauty & Wellness sector (products + services) 2025P | B5: 276999 | C5: ₹ crore | D5: S-IND-01 Table 1 | E5: Consumer spend on products and services
A6: Beauty & Salon sub-sector 2025P | B6: 76141 | C6: ₹ crore | D6: S-IND-01 Table 1 | E6: Salon services spend
A7: Makeup products (2024) | B7: 1.52 | C7: USD bn | D7: S-IND-51 | E7: Product sales
A8: Beauty salon services (2025) | B8: 12.6 | C8: USD bn | D8: S-IND-22 | E8: Services; vendor model
A9: Bridal makeup service spend (cross-check, base) | B9: 2880 | C9: ₹ crore | D9: india_market_analysis §8.4 | E9: Services demand for MUAs, not tuition
A10: Weddings: peak-season business 2025 | B10: 650000 | C10: ₹ crore | D10: S-IND-10 (CAIT) | E10: Wedding industry
A11: All-beauty paid training (mean, base) - wider education context | B11: =TAM_India!D36 -> 609.31406 | C11: ₹ crore | D11: TAM_India | E11: Includes non-makeup beauty courses; TAM is the makeup-led subset
A13: TAM (makeup-led paid tuition, base) for comparison | B13: =TAM_India!D30 -> 387.74531

Sheet Checks
A1: Integrity checks (TRUE = pass)
A4: Check | B4: Result | C4: Detail
A5: TAM_India Method 1 base reproduces research (₹522.1 crore ±1) | B5: =ABS(TAM_India!D14-522.1)<1 -> TRUE
A6: TAM base reproduces CA-06 (₹387.7 crore ±1) | B6: =ABS(TAM_India!D30-387.7)<1 -> TRUE
A7: CA-05 base reproduces research (₹5.65 crore ±0.1) | B7: =ABS(Tricity_Recon!D16-5.65)<0.1 -> TRUE
A8: Reconciled tricity base lies between Method A and Method B | B8: =AND(Tricity_Recon!D46>=Tricity_Recon!D28,Tricity_Recon!D46<=Tricity_Recon!D34) -> TRUE
A9: Low <= Base <= High for reconciled tricity revenue | B9: =AND(Tricity_Recon!C47<=Tricity_Recon!D47,Tricity_Recon!D47<=Tricity_Recon!E47) -> TRUE
A10: SAM total < TAM incl. online (all cases) | B10: =AND(SAM_North!C40<TAM_India!C34,SAM_North!D40<TAM_India!D34,SAM_North!E40<TAM_India!E34) -> TRUE
A11: SOM < SAM total (all cases) | B11: =AND(SOM_PNA!C21<SAM_North!C40,SOM_PNA!D21<SAM_North!D40,SOM_PNA!E21<SAM_North!E40) -> TRUE
A12: Base SOM learner share of tricity <= 25% (revenue share shown separately) | B12: =SOM_PNA!D17<=0.25 -> TRUE
A13: KPMG tricity intensity within 10% of affluence weight (cross-check) | B13: =ABS(Tricity_Recon!D12/Tricity_Recon!D10-1)<0.1 -> TRUE
A15: All checks pass | B15: =AND(B5:B13) -> TRUE
